/var/runtime/botocore/vendored/requests/__init__.py:91: RequestsDependencyWarning: urllib3 (1.26.4) or chardet (4.0.0) doesn't match a supported version!
RequestsDependencyWarning)
START RequestId: XXXX Version: $LATEST
{"m": "aws.lambda.enhanced.invocations", "v": 1, "e": XXXX, "t": ["region:us-east-1", "account_id:XXXX", "functionname:integration-dev-http-error_python36", "resource:integration-dev-http-error_python36", "cold_start:true", "memorysize:1024", "runtime:python3.6", "datadog_lambda:vXX", "dd_lambda_layer:datadog-python36_2.XX.0"]}
HTTP GET https://httpstat.us/400/ Headers: ["Accept-Encoding:gzip, deflate", "Accept:*/*", "Connection:keep-alive", "User-Agent:python-requests/2.25.1", "x-datadog-parent-id:XXXX", "x-datadog-sampling-priority:1", "x-datadog-trace-id:XXXX"] Data: {}
2021-03-24 18:59:52.889 (-04:00)	5c252990-8685-4a74-b019-e5fee7366773	[ERROR]	[dd.trace_id=11497925091498312598 dd.span_id=11468057014981743396]	Error flushing metrics and events
Traceback (most recent call last):
  File "/opt/python/lib/python3.6/site-packages/datadog/threadstats/base.py", line 343, in flush
    self.reporter.flush_distributions(dists)
  File "/opt/python/lib/python3.6/site-packages/datadog/threadstats/reporters.py", line 24, in flush_distributions
    api.Distribution.send(distributions, compress_payload=self.compress_payload)
  File "/opt/python/lib/python3.6/site-packages/datadog/api/distributions.py", line 43, in send
    attach_host_name=attach_host_name, compress_payload=compress_payload, **series_dict
  File "/opt/python/lib/python3.6/site-packages/datadog/api/resources.py", line 88, in send
    compress_payload=compress_payload
  File "/opt/python/lib/python3.6/site-packages/datadog/api/api_client.py", line 166, in submit
    proxies=_proxies, verify=_cacert
  File "/opt/python/lib/python3.6/site-packages/datadog/api/http_client.py", line 100, in request
    proxies=proxies, verify=verify)
  File "/opt/python/lib/python3.6/site-packages/requests/sessions.py", line 542, in request
    resp = self.send(prep, **send_kwargs)
  File "/opt/python/lib/python3.6/site-packages/ddtrace/contrib/requests/connection.py", line 95, in _wrap_send
    response = func(*args, **kwargs)
  File "/opt/python/lib/python3.6/site-packages/datadog_lambda/patch.py", line 133, in _log_request
    _print_request_string(request)
  File "/opt/python/lib/python3.6/site-packages/datadog_lambda/patch.py", line 147, in _print_request_string
    data_dict = json.loads(data)
  File "/var/lang/lib/python3.6/json/__init__.py", line 349, in loads
    s = s.decode(detect_encoding(s), 'surrogatepass')
UnicodeDecodeError: 'utf-8' codec can't decode byte 0x9c in position 1: invalid start byte{"traces": [[{"trace_id": "XXXX", "parent_id": "XXXX", "span_id": "XXXX", "service": "aws.lambda", "resource": "integration-dev-http-error_python36", "name": "aws.lambda", "error": 0, "start": XXXX, "duration": XXXX, "meta": {"_dd.origin": "lambda", "runtime-id": "XXXX", "cold_start": "true", "function_arn": "arn:aws:lambda:us-east-1:601427279990:function:integration-dev-http-error_python36", "function_version": "$LATEST", "request_id": "XXXX", "resource_names": "integration-dev-http-error_python36", "datadog_lambda": "X.X.X", "dd_trace": "X.X.X", "function_trigger.event_source": "api-gateway", "function_trigger.event_source_arn": "arn:aws:apigateway:us-east-1::/restapis/wt6mne2s9k/stages/test", "http.method": "GET", "http.status_code": "200"}, "metrics": {"_dd.agent_psr": 1.0, "system.pid": XXXX, "_sampling_priority_v1": 1}, "type": "serverless"}, {"trace_id": "XXXX", "parent_id": "XXXX", "span_id": "XXXX", "service": "aws.lambda", "resource": "requests.request", "name": "requests.request", "error": 0, "start": XXXX, "duration": XXXX, "meta": {"_dd.origin": "lambda", "http.method": "GET", "http.url": "https://httpstat.us/400/", "http.status_code": "400"}, "metrics": {"_dd.measured": 1}, "type": "http"}, {"trace_id": "XXXX", "parent_id": "XXXX", "span_id": "XXXX", "service": "aws.lambda", "resource": "requests.request", "name": "requests.request", "error": 1, "start": XXXX, "duration": XXXX, "meta": {"_dd.origin": "lambda", "http.method": "POST", "http.url": "https://api.datadoghq.com/api/v1/distribution_points", "error.msg": "'utf-8' codec can't decode byte 0x9c in position 1: invalid start byte", "error.type": "builtins.UnicodeDecodeError", "error.stack": "Traceback (most recent call last):\n  File \"/opt/python/lib/python3.6/site-packages/ddtrace/contrib/requests/connection.py\", line 95, in _wrap_send\n    response = func(*args, **kwargs)\n  File \"/opt/python/lib/python3.6/site-packages/datadog_lambda/patch.py\", line 133, in _log_request\n    _print_request_string(request)\n  File \"/opt/python/lib/python3.6/site-packages/datadog_lambda/patch.py\", line 147, in _print_request_string\n    data_dict = json.loads(data)\n  File \"/var/lang/lib/python3.6/json/__init__.py\", line 349, in loads\n    s = s.decode(detect_encoding(s), 'surrogatepass')\nUnicodeDecodeError: 'utf-8' codec can't decode byte 0x9c in position 1: invalid start byte\n"}, "metrics": {"_dd.measured": 1}, "type": "http"}]]}
END RequestId: XXXX
REPORT RequestId: XXXX	Duration: XXXX ms	Billed Duration: XXXX ms	Memory Size: 1024 MB	Max Memory Used: XXXX MB	Init Duration: XXXX ms	
XRAY TraceId: XXXX	SegmentId: XXXX	Sampled: true	
START RequestId: XXXX Version: $LATEST
{"m": "aws.lambda.enhanced.invocations", "v": 1, "e": XXXX, "t": ["region:us-east-1", "account_id:XXXX", "functionname:integration-dev-http-error_python36", "resource:integration-dev-http-error_python36", "cold_start:false", "memorysize:1024", "runtime:python3.6", "datadog_lambda:vXX", "dd_lambda_layer:datadog-python36_2.XX.0"]}
HTTP GET https://httpstat.us/400/ Headers: ["Accept-Encoding:gzip, deflate", "Accept:*/*", "Connection:keep-alive", "User-Agent:python-requests/2.25.1", "x-datadog-parent-id:XXXX", "x-datadog-sampling-priority:1", "x-datadog-trace-id:XXXX"] Data: {}
2021-03-24 18:59:54.588 (-04:00)	b5bd3e86-d09d-4cc6-b0e8-36c89ee9742a	[ERROR]	[dd.trace_id=16213641645043178534 dd.span_id=9531769101218159127]	Error flushing metrics and events
Traceback (most recent call last):
  File "/opt/python/lib/python3.6/site-packages/datadog/threadstats/base.py", line 343, in flush
    self.reporter.flush_distributions(dists)
  File "/opt/python/lib/python3.6/site-packages/datadog/threadstats/reporters.py", line 24, in flush_distributions
    api.Distribution.send(distributions, compress_payload=self.compress_payload)
  File "/opt/python/lib/python3.6/site-packages/datadog/api/distributions.py", line 43, in send
    attach_host_name=attach_host_name, compress_payload=compress_payload, **series_dict
  File "/opt/python/lib/python3.6/site-packages/datadog/api/resources.py", line 88, in send
    compress_payload=compress_payload
  File "/opt/python/lib/python3.6/site-packages/datadog/api/api_client.py", line 166, in submit
    proxies=_proxies, verify=_cacert
  File "/opt/python/lib/python3.6/site-packages/datadog/api/http_client.py", line 100, in request
    proxies=proxies, verify=verify)
  File "/opt/python/lib/python3.6/site-packages/requests/sessions.py", line 542, in request
    resp = self.send(prep, **send_kwargs)
  File "/opt/python/lib/python3.6/site-packages/ddtrace/contrib/requests/connection.py", line 95, in _wrap_send
    response = func(*args, **kwargs)
  File "/opt/python/lib/python3.6/site-packages/datadog_lambda/patch.py", line 133, in _log_request
    _print_request_string(request)
  File "/opt/python/lib/python3.6/site-packages/datadog_lambda/patch.py", line 147, in _print_request_string
    data_dict = json.loads(data)
  File "/var/lang/lib/python3.6/json/__init__.py", line 349, in loads
    s = s.decode(detect_encoding(s), 'surrogatepass')
UnicodeDecodeError: 'utf-8' codec can't decode byte 0x9c in position 1: invalid start byte{"traces": [[{"trace_id": "XXXX", "parent_id": "XXXX", "span_id": "XXXX", "service": "aws.lambda", "resource": "integration-dev-http-error_python36", "name": "aws.lambda", "error": 0, "start": XXXX, "duration": XXXX, "meta": {"_dd.origin": "lambda", "runtime-id": "XXXX", "cold_start": "false", "function_arn": "arn:aws:lambda:us-east-1:601427279990:function:integration-dev-http-error_python36", "function_version": "$LATEST", "request_id": "XXXX", "resource_names": "integration-dev-http-error_python36", "datadog_lambda": "X.X.X", "dd_trace": "X.X.X", "function_trigger.event_source": "sns", "function_trigger.event_source_arn": "arn:aws:sns:us-east-2:123456789012:sns-lambda"}, "metrics": {"_dd.agent_psr": 1.0, "system.pid": XXXX, "_sampling_priority_v1": 1}, "type": "serverless"}, {"trace_id": "XXXX", "parent_id": "XXXX", "span_id": "XXXX", "service": "aws.lambda", "resource": "requests.request", "name": "requests.request", "error": 0, "start": XXXX, "duration": XXXX, "meta": {"_dd.origin": "lambda", "http.method": "GET", "http.url": "https://httpstat.us/400/", "http.status_code": "400"}, "metrics": {"_dd.measured": 1}, "type": "http"}, {"trace_id": "XXXX", "parent_id": "XXXX", "span_id": "XXXX", "service": "aws.lambda", "resource": "requests.request", "name": "requests.request", "error": 1, "start": XXXX, "duration": XXXX, "meta": {"_dd.origin": "lambda", "http.method": "POST", "http.url": "https://api.datadoghq.com/api/v1/distribution_points", "error.msg": "'utf-8' codec can't decode byte 0x9c in position 1: invalid start byte", "error.type": "builtins.UnicodeDecodeError", "error.stack": "Traceback (most recent call last):\n  File \"/opt/python/lib/python3.6/site-packages/ddtrace/contrib/requests/connection.py\", line 95, in _wrap_send\n    response = func(*args, **kwargs)\n  File \"/opt/python/lib/python3.6/site-packages/datadog_lambda/patch.py\", line 133, in _log_request\n    _print_request_string(request)\n  File \"/opt/python/lib/python3.6/site-packages/datadog_lambda/patch.py\", line 147, in _print_request_string\n    data_dict = json.loads(data)\n  File \"/var/lang/lib/python3.6/json/__init__.py\", line 349, in loads\n    s = s.decode(detect_encoding(s), 'surrogatepass')\nUnicodeDecodeError: 'utf-8' codec can't decode byte 0x9c in position 1: invalid start byte\n"}, "metrics": {"_dd.measured": 1}, "type": "http"}]]}
END RequestId: XXXX
REPORT RequestId: XXXX	Duration: XXXX ms	Billed Duration: XXXX ms	Memory Size: 1024 MB	Max Memory Used: XXXX MB	
XRAY TraceId: XXXX	SegmentId: XXXX	Sampled: true	
START RequestId: XXXX Version: $LATEST
{"m": "aws.lambda.enhanced.invocations", "v": 1, "e": XXXX, "t": ["region:us-east-1", "account_id:XXXX", "functionname:integration-dev-http-error_python36", "resource:integration-dev-http-error_python36", "cold_start:false", "memorysize:1024", "runtime:python3.6", "datadog_lambda:vXX", "dd_lambda_layer:datadog-python36_2.XX.0"]}
HTTP GET https://httpstat.us/400/ Headers: ["Accept-Encoding:gzip, deflate", "Accept:*/*", "Connection:keep-alive", "User-Agent:python-requests/2.25.1", "x-datadog-parent-id:XXXX", "x-datadog-sampling-priority:1", "x-datadog-trace-id:XXXX"] Data: {}
2021-03-24 18:59:56.343 (-04:00)	e5cdada1-079e-40af-9c67-f98e45790a02	[ERROR]	[dd.trace_id=666 dd.span_id=13153769908384418899]	Error flushing metrics and events
Traceback (most recent call last):
  File "/opt/python/lib/python3.6/site-packages/datadog/threadstats/base.py", line 343, in flush
    self.reporter.flush_distributions(dists)
  File "/opt/python/lib/python3.6/site-packages/datadog/threadstats/reporters.py", line 24, in flush_distributions
    api.Distribution.send(distributions, compress_payload=self.compress_payload)
  File "/opt/python/lib/python3.6/site-packages/datadog/api/distributions.py", line 43, in send
    attach_host_name=attach_host_name, compress_payload=compress_payload, **series_dict
  File "/opt/python/lib/python3.6/site-packages/datadog/api/resources.py", line 88, in send
    compress_payload=compress_payload
  File "/opt/python/lib/python3.6/site-packages/datadog/api/api_client.py", line 166, in submit
    proxies=_proxies, verify=_cacert
  File "/opt/python/lib/python3.6/site-packages/datadog/api/http_client.py", line 100, in request
    proxies=proxies, verify=verify)
  File "/opt/python/lib/python3.6/site-packages/requests/sessions.py", line 542, in request
    resp = self.send(prep, **send_kwargs)
  File "/opt/python/lib/python3.6/site-packages/ddtrace/contrib/requests/connection.py", line 95, in _wrap_send
    response = func(*args, **kwargs)
  File "/opt/python/lib/python3.6/site-packages/datadog_lambda/patch.py", line 133, in _log_request
    _print_request_string(request)
  File "/opt/python/lib/python3.6/site-packages/datadog_lambda/patch.py", line 147, in _print_request_string
    data_dict = json.loads(data)
  File "/var/lang/lib/python3.6/json/__init__.py", line 349, in loads
    s = s.decode(detect_encoding(s), 'surrogatepass')
UnicodeDecodeError: 'utf-8' codec can't decode byte 0x9c in position 1: invalid start byte{"traces": [[{"trace_id": "XXXX", "parent_id": "XXXX", "span_id": "XXXX", "service": "aws.lambda", "resource": "integration-dev-http-error_python36", "name": "aws.lambda", "error": 0, "start": XXXX, "duration": XXXX, "meta": {"_dd.origin": "lambda", "runtime-id": "XXXX", "cold_start": "false", "function_arn": "arn:aws:lambda:us-east-1:601427279990:function:integration-dev-http-error_python36", "function_version": "$LATEST", "request_id": "XXXX", "resource_names": "integration-dev-http-error_python36", "datadog_lambda": "X.X.X", "dd_trace": "X.X.X", "function_trigger.event_source": "sqs", "function_trigger.event_source_arn": "arn:aws:sqs:us-east-2:123456789012:my-queue"}, "metrics": {"system.pid": XXXX, "_sampling_priority_v1": 1}, "type": "serverless"}, {"trace_id": "XXXX", "parent_id": "XXXX", "span_id": "XXXX", "service": "aws.lambda", "resource": "requests.request", "name": "requests.request", "error": 0, "start": XXXX, "duration": XXXX, "meta": {"_dd.origin": "lambda", "http.method": "GET", "http.url": "https://httpstat.us/400/", "http.status_code": "400"}, "metrics": {"_dd.measured": 1}, "type": "http"}, {"trace_id": "XXXX", "parent_id": "XXXX", "span_id": "XXXX", "service": "aws.lambda", "resource": "requests.request", "name": "requests.request", "error": 1, "start": XXXX, "duration": XXXX, "meta": {"_dd.origin": "lambda", "http.method": "POST", "http.url": "https://api.datadoghq.com/api/v1/distribution_points", "error.msg": "'utf-8' codec can't decode byte 0x9c in position 1: invalid start byte", "error.type": "builtins.UnicodeDecodeError", "error.stack": "Traceback (most recent call last):\n  File \"/opt/python/lib/python3.6/site-packages/ddtrace/contrib/requests/connection.py\", line 95, in _wrap_send\n    response = func(*args, **kwargs)\n  File \"/opt/python/lib/python3.6/site-packages/datadog_lambda/patch.py\", line 133, in _log_request\n    _print_request_string(request)\n  File \"/opt/python/lib/python3.6/site-packages/datadog_lambda/patch.py\", line 147, in _print_request_string\n    data_dict = json.loads(data)\n  File \"/var/lang/lib/python3.6/json/__init__.py\", line 349, in loads\n    s = s.decode(detect_encoding(s), 'surrogatepass')\nUnicodeDecodeError: 'utf-8' codec can't decode byte 0x9c in position 1: invalid start byte\n"}, "metrics": {"_dd.measured": 1}, "type": "http"}]]}
END RequestId: XXXX
REPORT RequestId: XXXX	Duration: XXXX ms	Billed Duration: XXXX ms	Memory Size: 1024 MB	Max Memory Used: XXXX MB	
XRAY TraceId: XXXX	SegmentId: XXXX	Sampled: true	
/var/runtime/botocore/vendored/requests/__init__.py:91: RequestsDependencyWarning: urllib3 (1.26.4) or chardet (4.0.0) doesn't match a supported version!
RequestsDependencyWarning)
START RequestId: XXXX Version: $LATEST
{"m": "aws.lambda.enhanced.invocations", "v": 1, "e": XXXX, "t": ["region:us-east-1", "account_id:XXXX", "functionname:integration-dev-http-error_python36", "resource:integration-dev-http-error_python36", "cold_start:true", "memorysize:1024", "runtime:python3.6", "datadog_lambda:vXX", "dd_lambda_layer:datadog-python36_2.XX.0"]}
HTTP GET https://httpstat.us/400/ Headers: ["Accept-Encoding:gzip, deflate", "Accept:*/*", "Connection:keep-alive", "User-Agent:python-requests/2.25.1", "x-datadog-parent-id:XXXX", "x-datadog-sampling-priority:1", "x-datadog-trace-id:XXXX"] Data: {}
2021-03-24 19:21:27.882 (-04:00)	968213f1-35ce-4fa4-835b-6799783a93af	[ERROR]	[dd.trace_id=17772950656934427352 dd.span_id=2148790547052643563]	Error flushing metrics and events
Traceback (most recent call last):
  File "/opt/python/lib/python3.6/site-packages/datadog/threadstats/base.py", line 343, in flush
    self.reporter.flush_distributions(dists)
  File "/opt/python/lib/python3.6/site-packages/datadog/threadstats/reporters.py", line 24, in flush_distributions
    api.Distribution.send(distributions, compress_payload=self.compress_payload)
  File "/opt/python/lib/python3.6/site-packages/datadog/api/distributions.py", line 43, in send
    attach_host_name=attach_host_name, compress_payload=compress_payload, **series_dict
  File "/opt/python/lib/python3.6/site-packages/datadog/api/resources.py", line 88, in send
    compress_payload=compress_payload
  File "/opt/python/lib/python3.6/site-packages/datadog/api/api_client.py", line 166, in submit
    proxies=_proxies, verify=_cacert
  File "/opt/python/lib/python3.6/site-packages/datadog/api/http_client.py", line 100, in request
    proxies=proxies, verify=verify)
  File "/opt/python/lib/python3.6/site-packages/requests/sessions.py", line 542, in request
    resp = self.send(prep, **send_kwargs)
  File "/opt/python/lib/python3.6/site-packages/ddtrace/contrib/requests/connection.py", line 95, in _wrap_send
    response = func(*args, **kwargs)
  File "/opt/python/lib/python3.6/site-packages/datadog_lambda/patch.py", line 133, in _log_request
    _print_request_string(request)
  File "/opt/python/lib/python3.6/site-packages/datadog_lambda/patch.py", line 147, in _print_request_string
    data_dict = json.loads(data)
  File "/var/lang/lib/python3.6/json/__init__.py", line 349, in loads
    s = s.decode(detect_encoding(s), 'surrogatepass')
UnicodeDecodeError: 'utf-8' codec can't decode byte 0x9c in position 1: invalid start byte{"traces": [[{"trace_id": "XXXX", "parent_id": "XXXX", "span_id": "XXXX", "service": "aws.lambda", "resource": "integration-dev-http-error_python36", "name": "aws.lambda", "error": 0, "start": XXXX, "duration": XXXX, "meta": {"_dd.origin": "lambda", "runtime-id": "XXXX", "cold_start": "true", "function_arn": "arn:aws:lambda:us-east-1:601427279990:function:integration-dev-http-error_python36", "function_version": "$LATEST", "request_id": "XXXX", "resource_names": "integration-dev-http-error_python36", "datadog_lambda": "X.X.X", "dd_trace": "X.X.X", "function_trigger.event_source": "api-gateway", "function_trigger.event_source_arn": "arn:aws:apigateway:us-east-1::/restapis/wt6mne2s9k/stages/test", "http.method": "GET", "http.status_code": "200"}, "metrics": {"_dd.agent_psr": 1.0, "system.pid": XXXX, "_sampling_priority_v1": 1}, "type": "serverless"}, {"trace_id": "XXXX", "parent_id": "XXXX", "span_id": "XXXX", "service": "aws.lambda", "resource": "requests.request", "name": "requests.request", "error": 0, "start": XXXX, "duration": XXXX, "meta": {"_dd.origin": "lambda", "http.method": "GET", "http.url": "https://httpstat.us/400/", "http.status_code": "400"}, "metrics": {"_dd.measured": 1}, "type": "http"}, {"trace_id": "XXXX", "parent_id": "XXXX", "span_id": "XXXX", "service": "aws.lambda", "resource": "requests.request", "name": "requests.request", "error": 1, "start": XXXX, "duration": XXXX, "meta": {"_dd.origin": "lambda", "http.method": "POST", "http.url": "https://api.datadoghq.com/api/v1/distribution_points", "error.msg": "'utf-8' codec can't decode byte 0x9c in position 1: invalid start byte", "error.type": "builtins.UnicodeDecodeError", "error.stack": "Traceback (most recent call last):\n  File \"/opt/python/lib/python3.6/site-packages/ddtrace/contrib/requests/connection.py\", line 95, in _wrap_send\n    response = func(*args, **kwargs)\n  File \"/opt/python/lib/python3.6/site-packages/datadog_lambda/patch.py\", line 133, in _log_request\n    _print_request_string(request)\n  File \"/opt/python/lib/python3.6/site-packages/datadog_lambda/patch.py\", line 147, in _print_request_string\n    data_dict = json.loads(data)\n  File \"/var/lang/lib/python3.6/json/__init__.py\", line 349, in loads\n    s = s.decode(detect_encoding(s), 'surrogatepass')\nUnicodeDecodeError: 'utf-8' codec can't decode byte 0x9c in position 1: invalid start byte\n"}, "metrics": {"_dd.measured": 1}, "type": "http"}]]}
END RequestId: XXXX
REPORT RequestId: XXXX	Duration: XXXX ms	Billed Duration: XXXX ms	Memory Size: 1024 MB	Max Memory Used: XXXX MB	Init Duration: XXXX ms	
XRAY TraceId: XXXX	SegmentId: XXXX	Sampled: true	
START RequestId: XXXX Version: $LATEST
{"m": "aws.lambda.enhanced.invocations", "v": 1, "e": XXXX, "t": ["region:us-east-1", "account_id:XXXX", "functionname:integration-dev-http-error_python36", "resource:integration-dev-http-error_python36", "cold_start:false", "memorysize:1024", "runtime:python3.6", "datadog_lambda:vXX", "dd_lambda_layer:datadog-python36_2.XX.0"]}
HTTP GET https://httpstat.us/400/ Headers: ["Accept-Encoding:gzip, deflate", "Accept:*/*", "Connection:keep-alive", "User-Agent:python-requests/2.25.1", "x-datadog-parent-id:XXXX", "x-datadog-sampling-priority:1", "x-datadog-trace-id:XXXX"] Data: {}
2021-03-24 19:21:29.375 (-04:00)	c9f693d9-9c3e-4168-9074-973988ec84a8	[ERROR]	[dd.trace_id=235209785309035760 dd.span_id=5387326214520946711]	Error flushing metrics and events
Traceback (most recent call last):
  File "/opt/python/lib/python3.6/site-packages/datadog/threadstats/base.py", line 343, in flush
    self.reporter.flush_distributions(dists)
  File "/opt/python/lib/python3.6/site-packages/datadog/threadstats/reporters.py", line 24, in flush_distributions
    api.Distribution.send(distributions, compress_payload=self.compress_payload)
  File "/opt/python/lib/python3.6/site-packages/datadog/api/distributions.py", line 43, in send
    attach_host_name=attach_host_name, compress_payload=compress_payload, **series_dict
  File "/opt/python/lib/python3.6/site-packages/datadog/api/resources.py", line 88, in send
    compress_payload=compress_payload
  File "/opt/python/lib/python3.6/site-packages/datadog/api/api_client.py", line 166, in submit
    proxies=_proxies, verify=_cacert
  File "/opt/python/lib/python3.6/site-packages/datadog/api/http_client.py", line 100, in request
    proxies=proxies, verify=verify)
  File "/opt/python/lib/python3.6/site-packages/requests/sessions.py", line 542, in request
    resp = self.send(prep, **send_kwargs)
  File "/opt/python/lib/python3.6/site-packages/ddtrace/contrib/requests/connection.py", line 95, in _wrap_send
    response = func(*args, **kwargs)
  File "/opt/python/lib/python3.6/site-packages/datadog_lambda/patch.py", line 133, in _log_request
    _print_request_string(request)
  File "/opt/python/lib/python3.6/site-packages/datadog_lambda/patch.py", line 147, in _print_request_string
    data_dict = json.loads(data)
  File "/var/lang/lib/python3.6/json/__init__.py", line 349, in loads
    s = s.decode(detect_encoding(s), 'surrogatepass')
UnicodeDecodeError: 'utf-8' codec can't decode byte 0x9c in position 1: invalid start byte{"traces": [[{"trace_id": "XXXX", "parent_id": "XXXX", "span_id": "XXXX", "service": "aws.lambda", "resource": "integration-dev-http-error_python36", "name": "aws.lambda", "error": 0, "start": XXXX, "duration": XXXX, "meta": {"_dd.origin": "lambda", "runtime-id": "XXXX", "cold_start": "false", "function_arn": "arn:aws:lambda:us-east-1:601427279990:function:integration-dev-http-error_python36", "function_version": "$LATEST", "request_id": "XXXX", "resource_names": "integration-dev-http-error_python36", "datadog_lambda": "X.X.X", "dd_trace": "X.X.X", "function_trigger.event_source": "sns", "function_trigger.event_source_arn": "arn:aws:sns:us-east-2:123456789012:sns-lambda"}, "metrics": {"_dd.agent_psr": 1.0, "system.pid": XXXX, "_sampling_priority_v1": 1}, "type": "serverless"}, {"trace_id": "XXXX", "parent_id": "XXXX", "span_id": "XXXX", "service": "aws.lambda", "resource": "requests.request", "name": "requests.request", "error": 0, "start": XXXX, "duration": XXXX, "meta": {"_dd.origin": "lambda", "http.method": "GET", "http.url": "https://httpstat.us/400/", "http.status_code": "400"}, "metrics": {"_dd.measured": 1}, "type": "http"}, {"trace_id": "XXXX", "parent_id": "XXXX", "span_id": "XXXX", "service": "aws.lambda", "resource": "requests.request", "name": "requests.request", "error": 1, "start": XXXX, "duration": XXXX, "meta": {"_dd.origin": "lambda", "http.method": "POST", "http.url": "https://api.datadoghq.com/api/v1/distribution_points", "error.msg": "'utf-8' codec can't decode byte 0x9c in position 1: invalid start byte", "error.type": "builtins.UnicodeDecodeError", "error.stack": "Traceback (most recent call last):\n  File \"/opt/python/lib/python3.6/site-packages/ddtrace/contrib/requests/connection.py\", line 95, in _wrap_send\n    response = func(*args, **kwargs)\n  File \"/opt/python/lib/python3.6/site-packages/datadog_lambda/patch.py\", line 133, in _log_request\n    _print_request_string(request)\n  File \"/opt/python/lib/python3.6/site-packages/datadog_lambda/patch.py\", line 147, in _print_request_string\n    data_dict = json.loads(data)\n  File \"/var/lang/lib/python3.6/json/__init__.py\", line 349, in loads\n    s = s.decode(detect_encoding(s), 'surrogatepass')\nUnicodeDecodeError: 'utf-8' codec can't decode byte 0x9c in position 1: invalid start byte\n"}, "metrics": {"_dd.measured": 1}, "type": "http"}]]}
END RequestId: XXXX
REPORT RequestId: XXXX	Duration: XXXX ms	Billed Duration: XXXX ms	Memory Size: 1024 MB	Max Memory Used: XXXX MB	
XRAY TraceId: XXXX	SegmentId: XXXX	Sampled: true	
START RequestId: XXXX Version: $LATEST
{"m": "aws.lambda.enhanced.invocations", "v": 1, "e": XXXX, "t": ["region:us-east-1", "account_id:XXXX", "functionname:integration-dev-http-error_python36", "resource:integration-dev-http-error_python36", "cold_start:false", "memorysize:1024", "runtime:python3.6", "datadog_lambda:vXX", "dd_lambda_layer:datadog-python36_2.XX.0"]}
HTTP GET https://httpstat.us/400/ Headers: ["Accept-Encoding:gzip, deflate", "Accept:*/*", "Connection:keep-alive", "User-Agent:python-requests/2.25.1", "x-datadog-parent-id:XXXX", "x-datadog-sampling-priority:1", "x-datadog-trace-id:XXXX"] Data: {}
2021-03-24 19:21:30.875 (-04:00)	55d25f64-e270-41c8-bd6f-883ef0d3eb61	[ERROR]	[dd.trace_id=666 dd.span_id=13241715821718233817]	Error flushing metrics and events
Traceback (most recent call last):
  File "/opt/python/lib/python3.6/site-packages/datadog/threadstats/base.py", line 343, in flush
    self.reporter.flush_distributions(dists)
  File "/opt/python/lib/python3.6/site-packages/datadog/threadstats/reporters.py", line 24, in flush_distributions
    api.Distribution.send(distributions, compress_payload=self.compress_payload)
  File "/opt/python/lib/python3.6/site-packages/datadog/api/distributions.py", line 43, in send
    attach_host_name=attach_host_name, compress_payload=compress_payload, **series_dict
  File "/opt/python/lib/python3.6/site-packages/datadog/api/resources.py", line 88, in send
    compress_payload=compress_payload
  File "/opt/python/lib/python3.6/site-packages/datadog/api/api_client.py", line 166, in submit
    proxies=_proxies, verify=_cacert
  File "/opt/python/lib/python3.6/site-packages/datadog/api/http_client.py", line 100, in request
    proxies=proxies, verify=verify)
  File "/opt/python/lib/python3.6/site-packages/requests/sessions.py", line 542, in request
    resp = self.send(prep, **send_kwargs)
  File "/opt/python/lib/python3.6/site-packages/ddtrace/contrib/requests/connection.py", line 95, in _wrap_send
    response = func(*args, **kwargs)
  File "/opt/python/lib/python3.6/site-packages/datadog_lambda/patch.py", line 133, in _log_request
    _print_request_string(request)
  File "/opt/python/lib/python3.6/site-packages/datadog_lambda/patch.py", line 147, in _print_request_string
    data_dict = json.loads(data)
  File "/var/lang/lib/python3.6/json/__init__.py", line 349, in loads
    s = s.decode(detect_encoding(s), 'surrogatepass')
UnicodeDecodeError: 'utf-8' codec can't decode byte 0x9c in position 1: invalid start byte{"traces": [[{"trace_id": "XXXX", "parent_id": "XXXX", "span_id": "XXXX", "service": "aws.lambda", "resource": "integration-dev-http-error_python36", "name": "aws.lambda", "error": 0, "start": XXXX, "duration": XXXX, "meta": {"_dd.origin": "lambda", "runtime-id": "XXXX", "cold_start": "false", "function_arn": "arn:aws:lambda:us-east-1:601427279990:function:integration-dev-http-error_python36", "function_version": "$LATEST", "request_id": "XXXX", "resource_names": "integration-dev-http-error_python36", "datadog_lambda": "X.X.X", "dd_trace": "X.X.X", "function_trigger.event_source": "sqs", "function_trigger.event_source_arn": "arn:aws:sqs:us-east-2:123456789012:my-queue"}, "metrics": {"system.pid": XXXX, "_sampling_priority_v1": 1}, "type": "serverless"}, {"trace_id": "XXXX", "parent_id": "XXXX", "span_id": "XXXX", "service": "aws.lambda", "resource": "requests.request", "name": "requests.request", "error": 0, "start": XXXX, "duration": XXXX, "meta": {"_dd.origin": "lambda", "http.method": "GET", "http.url": "https://httpstat.us/400/", "http.status_code": "400"}, "metrics": {"_dd.measured": 1}, "type": "http"}, {"trace_id": "XXXX", "parent_id": "XXXX", "span_id": "XXXX", "service": "aws.lambda", "resource": "requests.request", "name": "requests.request", "error": 1, "start": XXXX, "duration": XXXX, "meta": {"_dd.origin": "lambda", "http.method": "POST", "http.url": "https://api.datadoghq.com/api/v1/distribution_points", "error.msg": "'utf-8' codec can't decode byte 0x9c in position 1: invalid start byte", "error.type": "builtins.UnicodeDecodeError", "error.stack": "Traceback (most recent call last):\n  File \"/opt/python/lib/python3.6/site-packages/ddtrace/contrib/requests/connection.py\", line 95, in _wrap_send\n    response = func(*args, **kwargs)\n  File \"/opt/python/lib/python3.6/site-packages/datadog_lambda/patch.py\", line 133, in _log_request\n    _print_request_string(request)\n  File \"/opt/python/lib/python3.6/site-packages/datadog_lambda/patch.py\", line 147, in _print_request_string\n    data_dict = json.loads(data)\n  File \"/var/lang/lib/python3.6/json/__init__.py\", line 349, in loads\n    s = s.decode(detect_encoding(s), 'surrogatepass')\nUnicodeDecodeError: 'utf-8' codec can't decode byte 0x9c in position 1: invalid start byte\n"}, "metrics": {"_dd.measured": 1}, "type": "http"}]]}
END RequestId: XXXX
REPORT RequestId: XXXX	Duration: XXXX ms	Billed Duration: XXXX ms	Memory Size: 1024 MB	Max Memory Used: XXXX MB	
XRAY TraceId: XXXX	SegmentId: XXXX	Sampled: true	
