START RequestId: XXXX Version: $LATEST
{"m": "aws.lambda.enhanced.invocations", "v": 1, "e": XXXX, "t": ["region:us-east-1", "account_id:XXXX", "functionname:integration-dev-http-requests_python38", "resource:integration-dev-http-requests_python38", "cold_start:true", "memorysize:1024", "runtime:python3.8", "datadog_lambda:vXX", "dd_lambda_layer:datadog-python38_2.XX.0"]}
HTTP GET https://ip-ranges.datadoghq.com/ Headers: ["Accept-Encoding:gzip, deflate", "Accept:*/*", "Connection:keep-alive", "User-Agent:python-requests/2.25.1", "x-datadog-parent-id:XXXX", "x-datadog-sampling-priority:1", "x-datadog-trace-id:XXXX"] Data: {}
HTTP GET https://ip-ranges.datadoghq.eu/ Headers: ["Accept-Encoding:gzip, deflate", "Accept:*/*", "Connection:keep-alive", "User-Agent:python-requests/2.25.1", "x-datadog-parent-id:XXXX", "x-datadog-sampling-priority:1", "x-datadog-trace-id:XXXX"] Data: {}
2021-03-24 18:59:40.745 (-04:00)	56b999f5-116c-4357-b2f1-6f0725be0760	[ERROR]	[dd.trace_id=9450253238624095019 dd.span_id=3151850018983179783]	Error flushing metrics and events
Traceback (most recent call last):
  File "/opt/python/lib/python3.8/site-packages/datadog/threadstats/base.py", line 343, in flush
    self.reporter.flush_distributions(dists)
  File "/opt/python/lib/python3.8/site-packages/datadog/threadstats/reporters.py", line 24, in flush_distributions
    api.Distribution.send(distributions, compress_payload=self.compress_payload)
  File "/opt/python/lib/python3.8/site-packages/datadog/api/distributions.py", line 42, in send
    return super(Distribution, cls).send(
  File "/opt/python/lib/python3.8/site-packages/datadog/api/resources.py", line 82, in send
    return APIClient.submit(
  File "/opt/python/lib/python3.8/site-packages/datadog/api/api_client.py", line 162, in submit
    result = cls._get_http_client().request(
  File "/opt/python/lib/python3.8/site-packages/datadog/api/http_client.py", line 96, in request
    result = cls._session.request(
  File "/opt/python/lib/python3.8/site-packages/requests/sessions.py", line 542, in request
    resp = self.send(prep, **send_kwargs)
  File "/opt/python/lib/python3.8/site-packages/ddtrace/contrib/requests/connection.py", line 95, in _wrap_send
    response = func(*args, **kwargs)
  File "/opt/python/lib/python3.8/site-packages/datadog_lambda/patch.py", line 133, in _log_request
    _print_request_string(request)
  File "/opt/python/lib/python3.8/site-packages/datadog_lambda/patch.py", line 147, in _print_request_string
    data_dict = json.loads(data)
  File "/var/lang/lib/python3.8/json/__init__.py", line 343, in loads
    s = s.decode(detect_encoding(s), 'surrogatepass')
UnicodeDecodeError: 'utf-8' codec can't decode byte 0x9c in position 1: invalid start byte{"traces": [[{"trace_id": "XXXX", "parent_id": "XXXX", "span_id": "XXXX", "service": "aws.lambda", "resource": "integration-dev-http-requests_python38", "name": "aws.lambda", "error": 0, "start": XXXX, "duration": XXXX, "meta": {"_dd.origin": "lambda", "runtime-id": "XXXX", "cold_start": "true", "function_arn": "arn:aws:lambda:us-east-1:601427279990:function:integration-dev-http-requests_python38", "function_version": "$LATEST", "request_id": "XXXX", "resource_names": "integration-dev-http-requests_python38", "datadog_lambda": "X.X.X", "dd_trace": "X.X.X", "function_trigger.event_source": "api-gateway", "function_trigger.event_source_arn": "arn:aws:apigateway:us-east-1::/restapis/wt6mne2s9k/stages/test", "http.method": "GET", "http.status_code": "200"}, "metrics": {"_dd.agent_psr": 1.0, "system.pid": XXXX, "_sampling_priority_v1": 1}, "type": "serverless"}, {"trace_id": "XXXX", "parent_id": "XXXX", "span_id": "XXXX", "service": "aws.lambda", "resource": "requests.request", "name": "requests.request", "error": 0, "start": XXXX, "duration": XXXX, "meta": {"_dd.origin": "lambda", "http.method": "GET", "http.url": "https://ip-ranges.datadoghq.com/", "http.status_code": "200"}, "metrics": {"_dd.measured": 1}, "type": "http"}, {"trace_id": "XXXX", "parent_id": "XXXX", "span_id": "XXXX", "service": "aws.lambda", "resource": "requests.request", "name": "requests.request", "error": 0, "start": XXXX, "duration": XXXX, "meta": {"_dd.origin": "lambda", "http.method": "GET", "http.url": "https://ip-ranges.datadoghq.eu/", "http.status_code": "200"}, "metrics": {"_dd.measured": 1}, "type": "http"}, {"trace_id": "XXXX", "parent_id": "XXXX", "span_id": "XXXX", "service": "aws.lambda", "resource": "requests.request", "name": "requests.request", "error": 1, "start": XXXX, "duration": XXXX, "meta": {"_dd.origin": "lambda", "http.method": "POST", "http.url": "https://api.datadoghq.com/api/v1/distribution_points", "error.msg": "'utf-8' codec can't decode byte 0x9c in position 1: invalid start byte", "error.type": "builtins.UnicodeDecodeError", "error.stack": "Traceback (most recent call last):\n  File \"/opt/python/lib/python3.8/site-packages/ddtrace/contrib/requests/connection.py\", line 95, in _wrap_send\n    response = func(*args, **kwargs)\n  File \"/opt/python/lib/python3.8/site-packages/datadog_lambda/patch.py\", line 133, in _log_request\n    _print_request_string(request)\n  File \"/opt/python/lib/python3.8/site-packages/datadog_lambda/patch.py\", line 147, in _print_request_string\n    data_dict = json.loads(data)\n  File \"/var/lang/lib/python3.8/json/__init__.py\", line 343, in loads\n    s = s.decode(detect_encoding(s), 'surrogatepass')\nUnicodeDecodeError: 'utf-8' codec can't decode byte 0x9c in position 1: invalid start byte\n"}, "metrics": {"_dd.measured": 1}, "type": "http"}]]}
END RequestId: XXXX
REPORT RequestId: XXXX	Duration: XXXX ms	Billed Duration: XXXX ms	Memory Size: 1024 MB	Max Memory Used: XXXX MB	Init Duration: XXXX ms	
XRAY TraceId: XXXX	SegmentId: XXXX	Sampled: true	
START RequestId: XXXX Version: $LATEST
{"m": "aws.lambda.enhanced.invocations", "v": 1, "e": XXXX, "t": ["region:us-east-1", "account_id:XXXX", "functionname:integration-dev-http-requests_python38", "resource:integration-dev-http-requests_python38", "cold_start:false", "memorysize:1024", "runtime:python3.8", "datadog_lambda:vXX", "dd_lambda_layer:datadog-python38_2.XX.0"]}
HTTP GET https://ip-ranges.datadoghq.com/ Headers: ["Accept-Encoding:gzip, deflate", "Accept:*/*", "Connection:keep-alive", "User-Agent:python-requests/2.25.1", "x-datadog-parent-id:XXXX", "x-datadog-sampling-priority:1", "x-datadog-trace-id:XXXX"] Data: {}
HTTP GET https://ip-ranges.datadoghq.eu/ Headers: ["Accept-Encoding:gzip, deflate", "Accept:*/*", "Connection:keep-alive", "User-Agent:python-requests/2.25.1", "x-datadog-parent-id:XXXX", "x-datadog-sampling-priority:1", "x-datadog-trace-id:XXXX"] Data: {}
2021-03-24 18:59:42.513 (-04:00)	61d7586b-6a50-4c8f-93c9-8a893d398382	[ERROR]	[dd.trace_id=12441859865741085115 dd.span_id=8680574483151120373]	Error flushing metrics and events
Traceback (most recent call last):
  File "/opt/python/lib/python3.8/site-packages/datadog/threadstats/base.py", line 343, in flush
    self.reporter.flush_distributions(dists)
  File "/opt/python/lib/python3.8/site-packages/datadog/threadstats/reporters.py", line 24, in flush_distributions
    api.Distribution.send(distributions, compress_payload=self.compress_payload)
  File "/opt/python/lib/python3.8/site-packages/datadog/api/distributions.py", line 42, in send
    return super(Distribution, cls).send(
  File "/opt/python/lib/python3.8/site-packages/datadog/api/resources.py", line 82, in send
    return APIClient.submit(
  File "/opt/python/lib/python3.8/site-packages/datadog/api/api_client.py", line 162, in submit
    result = cls._get_http_client().request(
  File "/opt/python/lib/python3.8/site-packages/datadog/api/http_client.py", line 96, in request
    result = cls._session.request(
  File "/opt/python/lib/python3.8/site-packages/requests/sessions.py", line 542, in request
    resp = self.send(prep, **send_kwargs)
  File "/opt/python/lib/python3.8/site-packages/ddtrace/contrib/requests/connection.py", line 95, in _wrap_send
    response = func(*args, **kwargs)
  File "/opt/python/lib/python3.8/site-packages/datadog_lambda/patch.py", line 133, in _log_request
    _print_request_string(request)
  File "/opt/python/lib/python3.8/site-packages/datadog_lambda/patch.py", line 147, in _print_request_string
    data_dict = json.loads(data)
  File "/var/lang/lib/python3.8/json/__init__.py", line 343, in loads
    s = s.decode(detect_encoding(s), 'surrogatepass')
UnicodeDecodeError: 'utf-8' codec can't decode byte 0x9c in position 1: invalid start byte{"traces": [[{"trace_id": "XXXX", "parent_id": "XXXX", "span_id": "XXXX", "service": "aws.lambda", "resource": "integration-dev-http-requests_python38", "name": "aws.lambda", "error": 0, "start": XXXX, "duration": XXXX, "meta": {"_dd.origin": "lambda", "runtime-id": "XXXX", "cold_start": "false", "function_arn": "arn:aws:lambda:us-east-1:601427279990:function:integration-dev-http-requests_python38", "function_version": "$LATEST", "request_id": "XXXX", "resource_names": "integration-dev-http-requests_python38", "datadog_lambda": "X.X.X", "dd_trace": "X.X.X", "function_trigger.event_source": "sns", "function_trigger.event_source_arn": "arn:aws:sns:us-east-2:123456789012:sns-lambda"}, "metrics": {"_dd.agent_psr": 1.0, "system.pid": XXXX, "_sampling_priority_v1": 1}, "type": "serverless"}, {"trace_id": "XXXX", "parent_id": "XXXX", "span_id": "XXXX", "service": "aws.lambda", "resource": "requests.request", "name": "requests.request", "error": 0, "start": XXXX, "duration": XXXX, "meta": {"_dd.origin": "lambda", "http.method": "GET", "http.url": "https://ip-ranges.datadoghq.com/", "http.status_code": "200"}, "metrics": {"_dd.measured": 1}, "type": "http"}, {"trace_id": "XXXX", "parent_id": "XXXX", "span_id": "XXXX", "service": "aws.lambda", "resource": "requests.request", "name": "requests.request", "error": 0, "start": XXXX, "duration": XXXX, "meta": {"_dd.origin": "lambda", "http.method": "GET", "http.url": "https://ip-ranges.datadoghq.eu/", "http.status_code": "200"}, "metrics": {"_dd.measured": 1}, "type": "http"}, {"trace_id": "XXXX", "parent_id": "XXXX", "span_id": "XXXX", "service": "aws.lambda", "resource": "requests.request", "name": "requests.request", "error": 1, "start": XXXX, "duration": XXXX, "meta": {"_dd.origin": "lambda", "http.method": "POST", "http.url": "https://api.datadoghq.com/api/v1/distribution_points", "error.msg": "'utf-8' codec can't decode byte 0x9c in position 1: invalid start byte", "error.type": "builtins.UnicodeDecodeError", "error.stack": "Traceback (most recent call last):\n  File \"/opt/python/lib/python3.8/site-packages/ddtrace/contrib/requests/connection.py\", line 95, in _wrap_send\n    response = func(*args, **kwargs)\n  File \"/opt/python/lib/python3.8/site-packages/datadog_lambda/patch.py\", line 133, in _log_request\n    _print_request_string(request)\n  File \"/opt/python/lib/python3.8/site-packages/datadog_lambda/patch.py\", line 147, in _print_request_string\n    data_dict = json.loads(data)\n  File \"/var/lang/lib/python3.8/json/__init__.py\", line 343, in loads\n    s = s.decode(detect_encoding(s), 'surrogatepass')\nUnicodeDecodeError: 'utf-8' codec can't decode byte 0x9c in position 1: invalid start byte\n"}, "metrics": {"_dd.measured": 1}, "type": "http"}]]}
END RequestId: XXXX
REPORT RequestId: XXXX	Duration: XXXX ms	Billed Duration: XXXX ms	Memory Size: 1024 MB	Max Memory Used: XXXX MB	
XRAY TraceId: XXXX	SegmentId: XXXX	Sampled: true	
START RequestId: XXXX Version: $LATEST
{"m": "aws.lambda.enhanced.invocations", "v": 1, "e": XXXX, "t": ["region:us-east-1", "account_id:XXXX", "functionname:integration-dev-http-requests_python38", "resource:integration-dev-http-requests_python38", "cold_start:false", "memorysize:1024", "runtime:python3.8", "datadog_lambda:vXX", "dd_lambda_layer:datadog-python38_2.XX.0"]}
HTTP GET https://ip-ranges.datadoghq.com/ Headers: ["Accept-Encoding:gzip, deflate", "Accept:*/*", "Connection:keep-alive", "User-Agent:python-requests/2.25.1", "x-datadog-parent-id:XXXX", "x-datadog-sampling-priority:1", "x-datadog-trace-id:XXXX"] Data: {}
HTTP GET https://ip-ranges.datadoghq.eu/ Headers: ["Accept-Encoding:gzip, deflate", "Accept:*/*", "Connection:keep-alive", "User-Agent:python-requests/2.25.1", "x-datadog-parent-id:XXXX", "x-datadog-sampling-priority:1", "x-datadog-trace-id:XXXX"] Data: {}
2021-03-24 18:59:43.958 (-04:00)	e4d0e502-dfcd-42fd-a1c5-3524234eb39c	[ERROR]	[dd.trace_id=666 dd.span_id=9525499073315426063]	Error flushing metrics and events
Traceback (most recent call last):
  File "/opt/python/lib/python3.8/site-packages/datadog/threadstats/base.py", line 343, in flush
    self.reporter.flush_distributions(dists)
  File "/opt/python/lib/python3.8/site-packages/datadog/threadstats/reporters.py", line 24, in flush_distributions
    api.Distribution.send(distributions, compress_payload=self.compress_payload)
  File "/opt/python/lib/python3.8/site-packages/datadog/api/distributions.py", line 42, in send
    return super(Distribution, cls).send(
  File "/opt/python/lib/python3.8/site-packages/datadog/api/resources.py", line 82, in send
    return APIClient.submit(
  File "/opt/python/lib/python3.8/site-packages/datadog/api/api_client.py", line 162, in submit
    result = cls._get_http_client().request(
  File "/opt/python/lib/python3.8/site-packages/datadog/api/http_client.py", line 96, in request
    result = cls._session.request(
  File "/opt/python/lib/python3.8/site-packages/requests/sessions.py", line 542, in request
    resp = self.send(prep, **send_kwargs)
  File "/opt/python/lib/python3.8/site-packages/ddtrace/contrib/requests/connection.py", line 95, in _wrap_send
    response = func(*args, **kwargs)
  File "/opt/python/lib/python3.8/site-packages/datadog_lambda/patch.py", line 133, in _log_request
    _print_request_string(request)
  File "/opt/python/lib/python3.8/site-packages/datadog_lambda/patch.py", line 147, in _print_request_string
    data_dict = json.loads(data)
  File "/var/lang/lib/python3.8/json/__init__.py", line 343, in loads
    s = s.decode(detect_encoding(s), 'surrogatepass')
UnicodeDecodeError: 'utf-8' codec can't decode byte 0x9c in position 1: invalid start byte{"traces": [[{"trace_id": "XXXX", "parent_id": "XXXX", "span_id": "XXXX", "service": "aws.lambda", "resource": "integration-dev-http-requests_python38", "name": "aws.lambda", "error": 0, "start": XXXX, "duration": XXXX, "meta": {"_dd.origin": "lambda", "runtime-id": "XXXX", "cold_start": "false", "function_arn": "arn:aws:lambda:us-east-1:601427279990:function:integration-dev-http-requests_python38", "function_version": "$LATEST", "request_id": "XXXX", "resource_names": "integration-dev-http-requests_python38", "datadog_lambda": "X.X.X", "dd_trace": "X.X.X", "function_trigger.event_source": "sqs", "function_trigger.event_source_arn": "arn:aws:sqs:us-east-2:123456789012:my-queue"}, "metrics": {"system.pid": XXXX, "_sampling_priority_v1": 1}, "type": "serverless"}, {"trace_id": "XXXX", "parent_id": "XXXX", "span_id": "XXXX", "service": "aws.lambda", "resource": "requests.request", "name": "requests.request", "error": 0, "start": XXXX, "duration": XXXX, "meta": {"_dd.origin": "lambda", "http.method": "GET", "http.url": "https://ip-ranges.datadoghq.com/", "http.status_code": "200"}, "metrics": {"_dd.measured": 1}, "type": "http"}, {"trace_id": "XXXX", "parent_id": "XXXX", "span_id": "XXXX", "service": "aws.lambda", "resource": "requests.request", "name": "requests.request", "error": 0, "start": XXXX, "duration": XXXX, "meta": {"_dd.origin": "lambda", "http.method": "GET", "http.url": "https://ip-ranges.datadoghq.eu/", "http.status_code": "200"}, "metrics": {"_dd.measured": 1}, "type": "http"}, {"trace_id": "XXXX", "parent_id": "XXXX", "span_id": "XXXX", "service": "aws.lambda", "resource": "requests.request", "name": "requests.request", "error": 1, "start": XXXX, "duration": XXXX, "meta": {"_dd.origin": "lambda", "http.method": "POST", "http.url": "https://api.datadoghq.com/api/v1/distribution_points", "error.msg": "'utf-8' codec can't decode byte 0x9c in position 1: invalid start byte", "error.type": "builtins.UnicodeDecodeError", "error.stack": "Traceback (most recent call last):\n  File \"/opt/python/lib/python3.8/site-packages/ddtrace/contrib/requests/connection.py\", line 95, in _wrap_send\n    response = func(*args, **kwargs)\n  File \"/opt/python/lib/python3.8/site-packages/datadog_lambda/patch.py\", line 133, in _log_request\n    _print_request_string(request)\n  File \"/opt/python/lib/python3.8/site-packages/datadog_lambda/patch.py\", line 147, in _print_request_string\n    data_dict = json.loads(data)\n  File \"/var/lang/lib/python3.8/json/__init__.py\", line 343, in loads\n    s = s.decode(detect_encoding(s), 'surrogatepass')\nUnicodeDecodeError: 'utf-8' codec can't decode byte 0x9c in position 1: invalid start byte\n"}, "metrics": {"_dd.measured": 1}, "type": "http"}]]}
END RequestId: XXXX
REPORT RequestId: XXXX	Duration: XXXX ms	Billed Duration: XXXX ms	Memory Size: 1024 MB	Max Memory Used: XXXX MB	
XRAY TraceId: XXXX	SegmentId: XXXX	Sampled: true	
START RequestId: XXXX Version: $LATEST
{"m": "aws.lambda.enhanced.invocations", "v": 1, "e": XXXX, "t": ["region:us-east-1", "account_id:XXXX", "functionname:integration-dev-http-requests_python38", "resource:integration-dev-http-requests_python38", "cold_start:true", "memorysize:1024", "runtime:python3.8", "datadog_lambda:vXX", "dd_lambda_layer:datadog-python38_2.XX.0"]}
HTTP GET https://ip-ranges.datadoghq.com/ Headers: ["Accept-Encoding:gzip, deflate", "Accept:*/*", "Connection:keep-alive", "User-Agent:python-requests/2.25.1", "x-datadog-parent-id:XXXX", "x-datadog-sampling-priority:1", "x-datadog-trace-id:XXXX"] Data: {}
HTTP GET https://ip-ranges.datadoghq.eu/ Headers: ["Accept-Encoding:gzip, deflate", "Accept:*/*", "Connection:keep-alive", "User-Agent:python-requests/2.25.1", "x-datadog-parent-id:XXXX", "x-datadog-sampling-priority:1", "x-datadog-trace-id:XXXX"] Data: {}
2021-03-24 19:21:16.137 (-04:00)	dc53e37f-cf56-47f4-a3e4-3415acbdc7df	[ERROR]	[dd.trace_id=11087034238998079767 dd.span_id=12852653694580417131]	Error flushing metrics and events
Traceback (most recent call last):
  File "/opt/python/lib/python3.8/site-packages/datadog/threadstats/base.py", line 343, in flush
    self.reporter.flush_distributions(dists)
  File "/opt/python/lib/python3.8/site-packages/datadog/threadstats/reporters.py", line 24, in flush_distributions
    api.Distribution.send(distributions, compress_payload=self.compress_payload)
  File "/opt/python/lib/python3.8/site-packages/datadog/api/distributions.py", line 42, in send
    return super(Distribution, cls).send(
  File "/opt/python/lib/python3.8/site-packages/datadog/api/resources.py", line 82, in send
    return APIClient.submit(
  File "/opt/python/lib/python3.8/site-packages/datadog/api/api_client.py", line 162, in submit
    result = cls._get_http_client().request(
  File "/opt/python/lib/python3.8/site-packages/datadog/api/http_client.py", line 96, in request
    result = cls._session.request(
  File "/opt/python/lib/python3.8/site-packages/requests/sessions.py", line 542, in request
    resp = self.send(prep, **send_kwargs)
  File "/opt/python/lib/python3.8/site-packages/ddtrace/contrib/requests/connection.py", line 95, in _wrap_send
    response = func(*args, **kwargs)
  File "/opt/python/lib/python3.8/site-packages/datadog_lambda/patch.py", line 133, in _log_request
    _print_request_string(request)
  File "/opt/python/lib/python3.8/site-packages/datadog_lambda/patch.py", line 147, in _print_request_string
    data_dict = json.loads(data)
  File "/var/lang/lib/python3.8/json/__init__.py", line 343, in loads
    s = s.decode(detect_encoding(s), 'surrogatepass')
UnicodeDecodeError: 'utf-8' codec can't decode byte 0x9c in position 1: invalid start byte{"traces": [[{"trace_id": "XXXX", "parent_id": "XXXX", "span_id": "XXXX", "service": "aws.lambda", "resource": "integration-dev-http-requests_python38", "name": "aws.lambda", "error": 0, "start": XXXX, "duration": XXXX, "meta": {"_dd.origin": "lambda", "runtime-id": "XXXX", "cold_start": "true", "function_arn": "arn:aws:lambda:us-east-1:601427279990:function:integration-dev-http-requests_python38", "function_version": "$LATEST", "request_id": "XXXX", "resource_names": "integration-dev-http-requests_python38", "datadog_lambda": "X.X.X", "dd_trace": "X.X.X", "function_trigger.event_source": "api-gateway", "function_trigger.event_source_arn": "arn:aws:apigateway:us-east-1::/restapis/wt6mne2s9k/stages/test", "http.method": "GET", "http.status_code": "200"}, "metrics": {"_dd.agent_psr": 1.0, "system.pid": XXXX, "_sampling_priority_v1": 1}, "type": "serverless"}, {"trace_id": "XXXX", "parent_id": "XXXX", "span_id": "XXXX", "service": "aws.lambda", "resource": "requests.request", "name": "requests.request", "error": 0, "start": XXXX, "duration": XXXX, "meta": {"_dd.origin": "lambda", "http.method": "GET", "http.url": "https://ip-ranges.datadoghq.com/", "http.status_code": "200"}, "metrics": {"_dd.measured": 1}, "type": "http"}, {"trace_id": "XXXX", "parent_id": "XXXX", "span_id": "XXXX", "service": "aws.lambda", "resource": "requests.request", "name": "requests.request", "error": 0, "start": XXXX, "duration": XXXX, "meta": {"_dd.origin": "lambda", "http.method": "GET", "http.url": "https://ip-ranges.datadoghq.eu/", "http.status_code": "200"}, "metrics": {"_dd.measured": 1}, "type": "http"}, {"trace_id": "XXXX", "parent_id": "XXXX", "span_id": "XXXX", "service": "aws.lambda", "resource": "requests.request", "name": "requests.request", "error": 1, "start": XXXX, "duration": XXXX, "meta": {"_dd.origin": "lambda", "http.method": "POST", "http.url": "https://api.datadoghq.com/api/v1/distribution_points", "error.msg": "'utf-8' codec can't decode byte 0x9c in position 1: invalid start byte", "error.type": "builtins.UnicodeDecodeError", "error.stack": "Traceback (most recent call last):\n  File \"/opt/python/lib/python3.8/site-packages/ddtrace/contrib/requests/connection.py\", line 95, in _wrap_send\n    response = func(*args, **kwargs)\n  File \"/opt/python/lib/python3.8/site-packages/datadog_lambda/patch.py\", line 133, in _log_request\n    _print_request_string(request)\n  File \"/opt/python/lib/python3.8/site-packages/datadog_lambda/patch.py\", line 147, in _print_request_string\n    data_dict = json.loads(data)\n  File \"/var/lang/lib/python3.8/json/__init__.py\", line 343, in loads\n    s = s.decode(detect_encoding(s), 'surrogatepass')\nUnicodeDecodeError: 'utf-8' codec can't decode byte 0x9c in position 1: invalid start byte\n"}, "metrics": {"_dd.measured": 1}, "type": "http"}]]}
END RequestId: XXXX
REPORT RequestId: XXXX	Duration: XXXX ms	Billed Duration: XXXX ms	Memory Size: 1024 MB	Max Memory Used: XXXX MB	Init Duration: XXXX ms	
XRAY TraceId: XXXX	SegmentId: XXXX	Sampled: true	
START RequestId: XXXX Version: $LATEST
{"m": "aws.lambda.enhanced.invocations", "v": 1, "e": XXXX, "t": ["region:us-east-1", "account_id:XXXX", "functionname:integration-dev-http-requests_python38", "resource:integration-dev-http-requests_python38", "cold_start:false", "memorysize:1024", "runtime:python3.8", "datadog_lambda:vXX", "dd_lambda_layer:datadog-python38_2.XX.0"]}
HTTP GET https://ip-ranges.datadoghq.com/ Headers: ["Accept-Encoding:gzip, deflate", "Accept:*/*", "Connection:keep-alive", "User-Agent:python-requests/2.25.1", "x-datadog-parent-id:XXXX", "x-datadog-sampling-priority:1", "x-datadog-trace-id:XXXX"] Data: {}
HTTP GET https://ip-ranges.datadoghq.eu/ Headers: ["Accept-Encoding:gzip, deflate", "Accept:*/*", "Connection:keep-alive", "User-Agent:python-requests/2.25.1", "x-datadog-parent-id:XXXX", "x-datadog-sampling-priority:1", "x-datadog-trace-id:XXXX"] Data: {}
2021-03-24 19:21:17.590 (-04:00)	5f187541-41b2-462e-a988-753db0f66702	[ERROR]	[dd.trace_id=8912553342132246308 dd.span_id=17489177345452200630]	Error flushing metrics and events
Traceback (most recent call last):
  File "/opt/python/lib/python3.8/site-packages/datadog/threadstats/base.py", line 343, in flush
    self.reporter.flush_distributions(dists)
  File "/opt/python/lib/python3.8/site-packages/datadog/threadstats/reporters.py", line 24, in flush_distributions
    api.Distribution.send(distributions, compress_payload=self.compress_payload)
  File "/opt/python/lib/python3.8/site-packages/datadog/api/distributions.py", line 42, in send
    return super(Distribution, cls).send(
  File "/opt/python/lib/python3.8/site-packages/datadog/api/resources.py", line 82, in send
    return APIClient.submit(
  File "/opt/python/lib/python3.8/site-packages/datadog/api/api_client.py", line 162, in submit
    result = cls._get_http_client().request(
  File "/opt/python/lib/python3.8/site-packages/datadog/api/http_client.py", line 96, in request
    result = cls._session.request(
  File "/opt/python/lib/python3.8/site-packages/requests/sessions.py", line 542, in request
    resp = self.send(prep, **send_kwargs)
  File "/opt/python/lib/python3.8/site-packages/ddtrace/contrib/requests/connection.py", line 95, in _wrap_send
    response = func(*args, **kwargs)
  File "/opt/python/lib/python3.8/site-packages/datadog_lambda/patch.py", line 133, in _log_request
    _print_request_string(request)
  File "/opt/python/lib/python3.8/site-packages/datadog_lambda/patch.py", line 147, in _print_request_string
    data_dict = json.loads(data)
  File "/var/lang/lib/python3.8/json/__init__.py", line 343, in loads
    s = s.decode(detect_encoding(s), 'surrogatepass')
UnicodeDecodeError: 'utf-8' codec can't decode byte 0x9c in position 1: invalid start byte{"traces": [[{"trace_id": "XXXX", "parent_id": "XXXX", "span_id": "XXXX", "service": "aws.lambda", "resource": "integration-dev-http-requests_python38", "name": "aws.lambda", "error": 0, "start": XXXX, "duration": XXXX, "meta": {"_dd.origin": "lambda", "runtime-id": "XXXX", "cold_start": "false", "function_arn": "arn:aws:lambda:us-east-1:601427279990:function:integration-dev-http-requests_python38", "function_version": "$LATEST", "request_id": "XXXX", "resource_names": "integration-dev-http-requests_python38", "datadog_lambda": "X.X.X", "dd_trace": "X.X.X", "function_trigger.event_source": "sns", "function_trigger.event_source_arn": "arn:aws:sns:us-east-2:123456789012:sns-lambda"}, "metrics": {"_dd.agent_psr": 1.0, "system.pid": XXXX, "_sampling_priority_v1": 1}, "type": "serverless"}, {"trace_id": "XXXX", "parent_id": "XXXX", "span_id": "XXXX", "service": "aws.lambda", "resource": "requests.request", "name": "requests.request", "error": 0, "start": XXXX, "duration": XXXX, "meta": {"_dd.origin": "lambda", "http.method": "GET", "http.url": "https://ip-ranges.datadoghq.com/", "http.status_code": "200"}, "metrics": {"_dd.measured": 1}, "type": "http"}, {"trace_id": "XXXX", "parent_id": "XXXX", "span_id": "XXXX", "service": "aws.lambda", "resource": "requests.request", "name": "requests.request", "error": 0, "start": XXXX, "duration": XXXX, "meta": {"_dd.origin": "lambda", "http.method": "GET", "http.url": "https://ip-ranges.datadoghq.eu/", "http.status_code": "200"}, "metrics": {"_dd.measured": 1}, "type": "http"}, {"trace_id": "XXXX", "parent_id": "XXXX", "span_id": "XXXX", "service": "aws.lambda", "resource": "requests.request", "name": "requests.request", "error": 1, "start": XXXX, "duration": XXXX, "meta": {"_dd.origin": "lambda", "http.method": "POST", "http.url": "https://api.datadoghq.com/api/v1/distribution_points", "error.msg": "'utf-8' codec can't decode byte 0x9c in position 1: invalid start byte", "error.type": "builtins.UnicodeDecodeError", "error.stack": "Traceback (most recent call last):\n  File \"/opt/python/lib/python3.8/site-packages/ddtrace/contrib/requests/connection.py\", line 95, in _wrap_send\n    response = func(*args, **kwargs)\n  File \"/opt/python/lib/python3.8/site-packages/datadog_lambda/patch.py\", line 133, in _log_request\n    _print_request_string(request)\n  File \"/opt/python/lib/python3.8/site-packages/datadog_lambda/patch.py\", line 147, in _print_request_string\n    data_dict = json.loads(data)\n  File \"/var/lang/lib/python3.8/json/__init__.py\", line 343, in loads\n    s = s.decode(detect_encoding(s), 'surrogatepass')\nUnicodeDecodeError: 'utf-8' codec can't decode byte 0x9c in position 1: invalid start byte\n"}, "metrics": {"_dd.measured": 1}, "type": "http"}]]}
END RequestId: XXXX
REPORT RequestId: XXXX	Duration: XXXX ms	Billed Duration: XXXX ms	Memory Size: 1024 MB	Max Memory Used: XXXX MB	
XRAY TraceId: XXXX	SegmentId: XXXX	Sampled: true	
START RequestId: XXXX Version: $LATEST
{"m": "aws.lambda.enhanced.invocations", "v": 1, "e": XXXX, "t": ["region:us-east-1", "account_id:XXXX", "functionname:integration-dev-http-requests_python38", "resource:integration-dev-http-requests_python38", "cold_start:false", "memorysize:1024", "runtime:python3.8", "datadog_lambda:vXX", "dd_lambda_layer:datadog-python38_2.XX.0"]}
HTTP GET https://ip-ranges.datadoghq.com/ Headers: ["Accept-Encoding:gzip, deflate", "Accept:*/*", "Connection:keep-alive", "User-Agent:python-requests/2.25.1", "x-datadog-parent-id:XXXX", "x-datadog-sampling-priority:1", "x-datadog-trace-id:XXXX"] Data: {}
HTTP GET https://ip-ranges.datadoghq.eu/ Headers: ["Accept-Encoding:gzip, deflate", "Accept:*/*", "Connection:keep-alive", "User-Agent:python-requests/2.25.1", "x-datadog-parent-id:XXXX", "x-datadog-sampling-priority:1", "x-datadog-trace-id:XXXX"] Data: {}
2021-03-24 19:21:19.560 (-04:00)	710e0d76-8f87-4f35-8243-0c3fd380eb96	[ERROR]	[dd.trace_id=666 dd.span_id=7959521062397772185]	Error flushing metrics and events
Traceback (most recent call last):
  File "/opt/python/lib/python3.8/site-packages/datadog/threadstats/base.py", line 343, in flush
    self.reporter.flush_distributions(dists)
  File "/opt/python/lib/python3.8/site-packages/datadog/threadstats/reporters.py", line 24, in flush_distributions
    api.Distribution.send(distributions, compress_payload=self.compress_payload)
  File "/opt/python/lib/python3.8/site-packages/datadog/api/distributions.py", line 42, in send
    return super(Distribution, cls).send(
  File "/opt/python/lib/python3.8/site-packages/datadog/api/resources.py", line 82, in send
    return APIClient.submit(
  File "/opt/python/lib/python3.8/site-packages/datadog/api/api_client.py", line 162, in submit
    result = cls._get_http_client().request(
  File "/opt/python/lib/python3.8/site-packages/datadog/api/http_client.py", line 96, in request
    result = cls._session.request(
  File "/opt/python/lib/python3.8/site-packages/requests/sessions.py", line 542, in request
    resp = self.send(prep, **send_kwargs)
  File "/opt/python/lib/python3.8/site-packages/ddtrace/contrib/requests/connection.py", line 95, in _wrap_send
    response = func(*args, **kwargs)
  File "/opt/python/lib/python3.8/site-packages/datadog_lambda/patch.py", line 133, in _log_request
    _print_request_string(request)
  File "/opt/python/lib/python3.8/site-packages/datadog_lambda/patch.py", line 147, in _print_request_string
    data_dict = json.loads(data)
  File "/var/lang/lib/python3.8/json/__init__.py", line 343, in loads
    s = s.decode(detect_encoding(s), 'surrogatepass')
UnicodeDecodeError: 'utf-8' codec can't decode byte 0x9c in position 1: invalid start byte{"traces": [[{"trace_id": "XXXX", "parent_id": "XXXX", "span_id": "XXXX", "service": "aws.lambda", "resource": "integration-dev-http-requests_python38", "name": "aws.lambda", "error": 0, "start": XXXX, "duration": XXXX, "meta": {"_dd.origin": "lambda", "runtime-id": "XXXX", "cold_start": "false", "function_arn": "arn:aws:lambda:us-east-1:601427279990:function:integration-dev-http-requests_python38", "function_version": "$LATEST", "request_id": "XXXX", "resource_names": "integration-dev-http-requests_python38", "datadog_lambda": "X.X.X", "dd_trace": "X.X.X", "function_trigger.event_source": "sqs", "function_trigger.event_source_arn": "arn:aws:sqs:us-east-2:123456789012:my-queue"}, "metrics": {"system.pid": XXXX, "_sampling_priority_v1": 1}, "type": "serverless"}, {"trace_id": "XXXX", "parent_id": "XXXX", "span_id": "XXXX", "service": "aws.lambda", "resource": "requests.request", "name": "requests.request", "error": 0, "start": XXXX, "duration": XXXX, "meta": {"_dd.origin": "lambda", "http.method": "GET", "http.url": "https://ip-ranges.datadoghq.com/", "http.status_code": "200"}, "metrics": {"_dd.measured": 1}, "type": "http"}, {"trace_id": "XXXX", "parent_id": "XXXX", "span_id": "XXXX", "service": "aws.lambda", "resource": "requests.request", "name": "requests.request", "error": 0, "start": XXXX, "duration": XXXX, "meta": {"_dd.origin": "lambda", "http.method": "GET", "http.url": "https://ip-ranges.datadoghq.eu/", "http.status_code": "200"}, "metrics": {"_dd.measured": 1}, "type": "http"}, {"trace_id": "XXXX", "parent_id": "XXXX", "span_id": "XXXX", "service": "aws.lambda", "resource": "requests.request", "name": "requests.request", "error": 1, "start": XXXX, "duration": XXXX, "meta": {"_dd.origin": "lambda", "http.method": "POST", "http.url": "https://api.datadoghq.com/api/v1/distribution_points", "error.msg": "'utf-8' codec can't decode byte 0x9c in position 1: invalid start byte", "error.type": "builtins.UnicodeDecodeError", "error.stack": "Traceback (most recent call last):\n  File \"/opt/python/lib/python3.8/site-packages/ddtrace/contrib/requests/connection.py\", line 95, in _wrap_send\n    response = func(*args, **kwargs)\n  File \"/opt/python/lib/python3.8/site-packages/datadog_lambda/patch.py\", line 133, in _log_request\n    _print_request_string(request)\n  File \"/opt/python/lib/python3.8/site-packages/datadog_lambda/patch.py\", line 147, in _print_request_string\n    data_dict = json.loads(data)\n  File \"/var/lang/lib/python3.8/json/__init__.py\", line 343, in loads\n    s = s.decode(detect_encoding(s), 'surrogatepass')\nUnicodeDecodeError: 'utf-8' codec can't decode byte 0x9c in position 1: invalid start byte\n"}, "metrics": {"_dd.measured": 1}, "type": "http"}]]}
END RequestId: XXXX
REPORT RequestId: XXXX	Duration: XXXX ms	Billed Duration: XXXX ms	Memory Size: 1024 MB	Max Memory Used: XXXX MB	
XRAY TraceId: XXXX	SegmentId: XXXX	Sampled: true	
