START RequestId: XXXX Version: $LATEST
{"m": "aws.lambda.enhanced.invocations", "v": 1, "e": XXXX, "t": ["region:us-east-1", "account_id:XXXX", "functionname:integration-dev-http-error_python38", "resource:integration-dev-http-error_python38", "cold_start:true", "memorysize:1024", "runtime:python3.8", "datadog_lambda:vXX", "dd_lambda_layer:datadog-python38_2.XX.0"]}
HTTP GET https://httpstat.us/400/ Headers: ["Accept-Encoding:gzip, deflate", "Accept:*/*", "Connection:keep-alive", "User-Agent:python-requests/2.25.1", "x-datadog-parent-id:XXXX", "x-datadog-sampling-priority:1", "x-datadog-trace-id:XXXX"] Data: {}
2021-03-24 19:00:06.330 (-04:00)	d9ad51cd-8aa1-45ec-80c6-696367782edf	[ERROR]	[dd.trace_id=10497582272385693724 dd.span_id=3752126378111745594]	Error flushing metrics and events
Traceback (most recent call last):
  File "/opt/python/lib/python3.8/site-packages/datadog/threadstats/base.py", line 343, in flush
    self.reporter.flush_distributions(dists)
  File "/opt/python/lib/python3.8/site-packages/datadog/threadstats/reporters.py", line 24, in flush_distributions
    api.Distribution.send(distributions, compress_payload=self.compress_payload)
  File "/opt/python/lib/python3.8/site-packages/datadog/api/distributions.py", line 42, in send
    return super(Distribution, cls).send(
  File "/opt/python/lib/python3.8/site-packages/datadog/api/resources.py", line 82, in send
    return APIClient.submit(
  File "/opt/python/lib/python3.8/site-packages/datadog/api/api_client.py", line 162, in submit
    result = cls._get_http_client().request(
  File "/opt/python/lib/python3.8/site-packages/datadog/api/http_client.py", line 96, in request
    result = cls._session.request(
  File "/opt/python/lib/python3.8/site-packages/requests/sessions.py", line 542, in request
    resp = self.send(prep, **send_kwargs)
  File "/opt/python/lib/python3.8/site-packages/ddtrace/contrib/requests/connection.py", line 95, in _wrap_send
    response = func(*args, **kwargs)
  File "/opt/python/lib/python3.8/site-packages/datadog_lambda/patch.py", line 133, in _log_request
    _print_request_string(request)
  File "/opt/python/lib/python3.8/site-packages/datadog_lambda/patch.py", line 147, in _print_request_string
    data_dict = json.loads(data)
  File "/var/lang/lib/python3.8/json/__init__.py", line 343, in loads
    s = s.decode(detect_encoding(s), 'surrogatepass')
UnicodeDecodeError: 'utf-8' codec can't decode byte 0x9c in position 1: invalid start byteEND RequestId: XXXX
REPORT RequestId: XXXX	Duration: XXXX ms	Billed Duration: XXXX ms	Memory Size: 1024 MB	Max Memory Used: XXXX MB	Init Duration: XXXX ms	
XRAY TraceId: XXXX	SegmentId: XXXX	Sampled: true	
START RequestId: XXXX Version: $LATEST
{"traces": [[{"trace_id": "XXXX", "parent_id": "XXXX", "span_id": "XXXX", "service": "aws.lambda", "resource": "integration-dev-http-error_python38", "name": "aws.lambda", "error": 0, "start": XXXX, "duration": XXXX, "meta": {"_dd.origin": "lambda", "runtime-id": "XXXX", "cold_start": "true", "function_arn": "arn:aws:lambda:us-east-1:601427279990:function:integration-dev-http-error_python38", "function_version": "$LATEST", "request_id": "XXXX", "resource_names": "integration-dev-http-error_python38", "datadog_lambda": "X.X.X", "dd_trace": "X.X.X", "function_trigger.event_source": "api-gateway", "function_trigger.event_source_arn": "arn:aws:apigateway:us-east-1::/restapis/wt6mne2s9k/stages/test", "http.method": "GET", "http.status_code": "200"}, "metrics": {"_dd.agent_psr": 1.0, "system.pid": XXXX, "_sampling_priority_v1": 1}, "type": "serverless"}, {"trace_id": "XXXX", "parent_id": "XXXX", "span_id": "XXXX", "service": "aws.lambda", "resource": "requests.request", "name": "requests.request", "error": 0, "start": XXXX, "duration": XXXX, "meta": {"_dd.origin": "lambda", "http.method": "GET", "http.url": "https://httpstat.us/400/", "http.status_code": "400"}, "metrics": {"_dd.measured": 1}, "type": "http"}, {"trace_id": "XXXX", "parent_id": "XXXX", "span_id": "XXXX", "service": "aws.lambda", "resource": "requests.request", "name": "requests.request", "error": 1, "start": XXXX, "duration": XXXX, "meta": {"_dd.origin": "lambda", "http.method": "POST", "http.url": "https://api.datadoghq.com/api/v1/distribution_points", "error.msg": "'utf-8' codec can't decode byte 0x9c in position 1: invalid start byte", "error.type": "builtins.UnicodeDecodeError", "error.stack": "Traceback (most recent call last):\n  File \"/opt/python/lib/python3.8/site-packages/ddtrace/contrib/requests/connection.py\", line 95, in _wrap_send\n    response = func(*args, **kwargs)\n  File \"/opt/python/lib/python3.8/site-packages/datadog_lambda/patch.py\", line 133, in _log_request\n    _print_request_string(request)\n  File \"/opt/python/lib/python3.8/site-packages/datadog_lambda/patch.py\", line 147, in _print_request_string\n    data_dict = json.loads(data)\n  File \"/var/lang/lib/python3.8/json/__init__.py\", line 343, in loads\n    s = s.decode(detect_encoding(s), 'surrogatepass')\nUnicodeDecodeError: 'utf-8' codec can't decode byte 0x9c in position 1: invalid start byte\n"}, "metrics": {"_dd.measured": 1}, "type": "http"}]]}
{"m": "aws.lambda.enhanced.invocations", "v": 1, "e": XXXX, "t": ["region:us-east-1", "account_id:XXXX", "functionname:integration-dev-http-error_python38", "resource:integration-dev-http-error_python38", "cold_start:false", "memorysize:1024", "runtime:python3.8", "datadog_lambda:vXX", "dd_lambda_layer:datadog-python38_2.XX.0"]}
HTTP GET https://httpstat.us/400/ Headers: ["Accept-Encoding:gzip, deflate", "Accept:*/*", "Connection:keep-alive", "User-Agent:python-requests/2.25.1", "x-datadog-parent-id:XXXX", "x-datadog-sampling-priority:1", "x-datadog-trace-id:XXXX"] Data: {}
2021-03-24 19:00:07.995 (-04:00)	d654f8e9-ac30-4157-9434-595a1a9cc9b9	[ERROR]	[dd.trace_id=15346652115640502684 dd.span_id=514006717474287833]	Error flushing metrics and events
Traceback (most recent call last):
  File "/opt/python/lib/python3.8/site-packages/datadog/threadstats/base.py", line 343, in flush
    self.reporter.flush_distributions(dists)
  File "/opt/python/lib/python3.8/site-packages/datadog/threadstats/reporters.py", line 24, in flush_distributions
    api.Distribution.send(distributions, compress_payload=self.compress_payload)
  File "/opt/python/lib/python3.8/site-packages/datadog/api/distributions.py", line 42, in send
    return super(Distribution, cls).send(
  File "/opt/python/lib/python3.8/site-packages/datadog/api/resources.py", line 82, in send
    return APIClient.submit(
  File "/opt/python/lib/python3.8/site-packages/datadog/api/api_client.py", line 162, in submit
    result = cls._get_http_client().request(
  File "/opt/python/lib/python3.8/site-packages/datadog/api/http_client.py", line 96, in request
    result = cls._session.request(
  File "/opt/python/lib/python3.8/site-packages/requests/sessions.py", line 542, in request
    resp = self.send(prep, **send_kwargs)
  File "/opt/python/lib/python3.8/site-packages/ddtrace/contrib/requests/connection.py", line 95, in _wrap_send
    response = func(*args, **kwargs)
  File "/opt/python/lib/python3.8/site-packages/datadog_lambda/patch.py", line 133, in _log_request
    _print_request_string(request)
  File "/opt/python/lib/python3.8/site-packages/datadog_lambda/patch.py", line 147, in _print_request_string
    data_dict = json.loads(data)
  File "/var/lang/lib/python3.8/json/__init__.py", line 343, in loads
    s = s.decode(detect_encoding(s), 'surrogatepass')
UnicodeDecodeError: 'utf-8' codec can't decode byte 0x9c in position 1: invalid start byte{"traces": [[{"trace_id": "XXXX", "parent_id": "XXXX", "span_id": "XXXX", "service": "aws.lambda", "resource": "integration-dev-http-error_python38", "name": "aws.lambda", "error": 0, "start": XXXX, "duration": XXXX, "meta": {"_dd.origin": "lambda", "runtime-id": "XXXX", "cold_start": "false", "function_arn": "arn:aws:lambda:us-east-1:601427279990:function:integration-dev-http-error_python38", "function_version": "$LATEST", "request_id": "XXXX", "resource_names": "integration-dev-http-error_python38", "datadog_lambda": "X.X.X", "dd_trace": "X.X.X", "function_trigger.event_source": "sns", "function_trigger.event_source_arn": "arn:aws:sns:us-east-2:123456789012:sns-lambda"}, "metrics": {"_dd.agent_psr": 1.0, "system.pid": XXXX, "_sampling_priority_v1": 1}, "type": "serverless"}, {"trace_id": "XXXX", "parent_id": "XXXX", "span_id": "XXXX", "service": "aws.lambda", "resource": "requests.request", "name": "requests.request", "error": 0, "start": XXXX, "duration": XXXX, "meta": {"_dd.origin": "lambda", "http.method": "GET", "http.url": "https://httpstat.us/400/", "http.status_code": "400"}, "metrics": {"_dd.measured": 1}, "type": "http"}, {"trace_id": "XXXX", "parent_id": "XXXX", "span_id": "XXXX", "service": "aws.lambda", "resource": "requests.request", "name": "requests.request", "error": 1, "start": XXXX, "duration": XXXX, "meta": {"_dd.origin": "lambda", "http.method": "POST", "http.url": "https://api.datadoghq.com/api/v1/distribution_points", "error.msg": "'utf-8' codec can't decode byte 0x9c in position 1: invalid start byte", "error.type": "builtins.UnicodeDecodeError", "error.stack": "Traceback (most recent call last):\n  File \"/opt/python/lib/python3.8/site-packages/ddtrace/contrib/requests/connection.py\", line 95, in _wrap_send\n    response = func(*args, **kwargs)\n  File \"/opt/python/lib/python3.8/site-packages/datadog_lambda/patch.py\", line 133, in _log_request\n    _print_request_string(request)\n  File \"/opt/python/lib/python3.8/site-packages/datadog_lambda/patch.py\", line 147, in _print_request_string\n    data_dict = json.loads(data)\n  File \"/var/lang/lib/python3.8/json/__init__.py\", line 343, in loads\n    s = s.decode(detect_encoding(s), 'surrogatepass')\nUnicodeDecodeError: 'utf-8' codec can't decode byte 0x9c in position 1: invalid start byte\n"}, "metrics": {"_dd.measured": 1}, "type": "http"}]]}
END RequestId: XXXX
REPORT RequestId: XXXX	Duration: XXXX ms	Billed Duration: XXXX ms	Memory Size: 1024 MB	Max Memory Used: XXXX MB	
XRAY TraceId: XXXX	SegmentId: XXXX	Sampled: true	
START RequestId: XXXX Version: $LATEST
{"m": "aws.lambda.enhanced.invocations", "v": 1, "e": XXXX, "t": ["region:us-east-1", "account_id:XXXX", "functionname:integration-dev-http-error_python38", "resource:integration-dev-http-error_python38", "cold_start:false", "memorysize:1024", "runtime:python3.8", "datadog_lambda:vXX", "dd_lambda_layer:datadog-python38_2.XX.0"]}
HTTP GET https://httpstat.us/400/ Headers: ["Accept-Encoding:gzip, deflate", "Accept:*/*", "Connection:keep-alive", "User-Agent:python-requests/2.25.1", "x-datadog-parent-id:XXXX", "x-datadog-sampling-priority:1", "x-datadog-trace-id:XXXX"] Data: {}
2021-03-24 19:00:09.770 (-04:00)	f362653b-3415-40ac-8970-484f7683e00e	[ERROR]	[dd.trace_id=666 dd.span_id=3927022555270022483]	Error flushing metrics and events
Traceback (most recent call last):
  File "/opt/python/lib/python3.8/site-packages/datadog/threadstats/base.py", line 343, in flush
    self.reporter.flush_distributions(dists)
  File "/opt/python/lib/python3.8/site-packages/datadog/threadstats/reporters.py", line 24, in flush_distributions
    api.Distribution.send(distributions, compress_payload=self.compress_payload)
  File "/opt/python/lib/python3.8/site-packages/datadog/api/distributions.py", line 42, in send
    return super(Distribution, cls).send(
  File "/opt/python/lib/python3.8/site-packages/datadog/api/resources.py", line 82, in send
    return APIClient.submit(
  File "/opt/python/lib/python3.8/site-packages/datadog/api/api_client.py", line 162, in submit
    result = cls._get_http_client().request(
  File "/opt/python/lib/python3.8/site-packages/datadog/api/http_client.py", line 96, in request
    result = cls._session.request(
  File "/opt/python/lib/python3.8/site-packages/requests/sessions.py", line 542, in request
    resp = self.send(prep, **send_kwargs)
  File "/opt/python/lib/python3.8/site-packages/ddtrace/contrib/requests/connection.py", line 95, in _wrap_send
    response = func(*args, **kwargs)
  File "/opt/python/lib/python3.8/site-packages/datadog_lambda/patch.py", line 133, in _log_request
    _print_request_string(request)
  File "/opt/python/lib/python3.8/site-packages/datadog_lambda/patch.py", line 147, in _print_request_string
    data_dict = json.loads(data)
  File "/var/lang/lib/python3.8/json/__init__.py", line 343, in loads
    s = s.decode(detect_encoding(s), 'surrogatepass')
UnicodeDecodeError: 'utf-8' codec can't decode byte 0x9c in position 1: invalid start byte{"traces": [[{"trace_id": "XXXX", "parent_id": "XXXX", "span_id": "XXXX", "service": "aws.lambda", "resource": "integration-dev-http-error_python38", "name": "aws.lambda", "error": 0, "start": XXXX, "duration": XXXX, "meta": {"_dd.origin": "lambda", "runtime-id": "XXXX", "cold_start": "false", "function_arn": "arn:aws:lambda:us-east-1:601427279990:function:integration-dev-http-error_python38", "function_version": "$LATEST", "request_id": "XXXX", "resource_names": "integration-dev-http-error_python38", "datadog_lambda": "X.X.X", "dd_trace": "X.X.X", "function_trigger.event_source": "sqs", "function_trigger.event_source_arn": "arn:aws:sqs:us-east-2:123456789012:my-queue"}, "metrics": {"system.pid": XXXX, "_sampling_priority_v1": 1}, "type": "serverless"}, {"trace_id": "XXXX", "parent_id": "XXXX", "span_id": "XXXX", "service": "aws.lambda", "resource": "requests.request", "name": "requests.request", "error": 0, "start": XXXX, "duration": XXXX, "meta": {"_dd.origin": "lambda", "http.method": "GET", "http.url": "https://httpstat.us/400/", "http.status_code": "400"}, "metrics": {"_dd.measured": 1}, "type": "http"}, {"trace_id": "XXXX", "parent_id": "XXXX", "span_id": "XXXX", "service": "aws.lambda", "resource": "requests.request", "name": "requests.request", "error": 1, "start": XXXX, "duration": XXXX, "meta": {"_dd.origin": "lambda", "http.method": "POST", "http.url": "https://api.datadoghq.com/api/v1/distribution_points", "error.msg": "'utf-8' codec can't decode byte 0x9c in position 1: invalid start byte", "error.type": "builtins.UnicodeDecodeError", "error.stack": "Traceback (most recent call last):\n  File \"/opt/python/lib/python3.8/site-packages/ddtrace/contrib/requests/connection.py\", line 95, in _wrap_send\n    response = func(*args, **kwargs)\n  File \"/opt/python/lib/python3.8/site-packages/datadog_lambda/patch.py\", line 133, in _log_request\n    _print_request_string(request)\n  File \"/opt/python/lib/python3.8/site-packages/datadog_lambda/patch.py\", line 147, in _print_request_string\n    data_dict = json.loads(data)\n  File \"/var/lang/lib/python3.8/json/__init__.py\", line 343, in loads\n    s = s.decode(detect_encoding(s), 'surrogatepass')\nUnicodeDecodeError: 'utf-8' codec can't decode byte 0x9c in position 1: invalid start byte\n"}, "metrics": {"_dd.measured": 1}, "type": "http"}]]}
END RequestId: XXXX
REPORT RequestId: XXXX	Duration: XXXX ms	Billed Duration: XXXX ms	Memory Size: 1024 MB	Max Memory Used: XXXX MB	
XRAY TraceId: XXXX	SegmentId: XXXX	Sampled: true	
START RequestId: XXXX Version: $LATEST
{"m": "aws.lambda.enhanced.invocations", "v": 1, "e": XXXX, "t": ["region:us-east-1", "account_id:XXXX", "functionname:integration-dev-http-error_python38", "resource:integration-dev-http-error_python38", "cold_start:true", "memorysize:1024", "runtime:python3.8", "datadog_lambda:vXX", "dd_lambda_layer:datadog-python38_2.XX.0"]}
HTTP GET https://httpstat.us/400/ Headers: ["Accept-Encoding:gzip, deflate", "Accept:*/*", "Connection:keep-alive", "User-Agent:python-requests/2.25.1", "x-datadog-parent-id:XXXX", "x-datadog-sampling-priority:1", "x-datadog-trace-id:XXXX"] Data: {}
2021-03-24 19:21:39.841 (-04:00)	9c94953d-e781-4180-be79-a6c532218925	[ERROR]	[dd.trace_id=12623747568017993495 dd.span_id=3128026398867370790]	Error flushing metrics and events
Traceback (most recent call last):
  File "/opt/python/lib/python3.8/site-packages/datadog/threadstats/base.py", line 343, in flush
    self.reporter.flush_distributions(dists)
  File "/opt/python/lib/python3.8/site-packages/datadog/threadstats/reporters.py", line 24, in flush_distributions
    api.Distribution.send(distributions, compress_payload=self.compress_payload)
  File "/opt/python/lib/python3.8/site-packages/datadog/api/distributions.py", line 42, in send
    return super(Distribution, cls).send(
  File "/opt/python/lib/python3.8/site-packages/datadog/api/resources.py", line 82, in send
    return APIClient.submit(
  File "/opt/python/lib/python3.8/site-packages/datadog/api/api_client.py", line 162, in submit
    result = cls._get_http_client().request(
  File "/opt/python/lib/python3.8/site-packages/datadog/api/http_client.py", line 96, in request
    result = cls._session.request(
  File "/opt/python/lib/python3.8/site-packages/requests/sessions.py", line 542, in request
    resp = self.send(prep, **send_kwargs)
  File "/opt/python/lib/python3.8/site-packages/ddtrace/contrib/requests/connection.py", line 95, in _wrap_send
    response = func(*args, **kwargs)
  File "/opt/python/lib/python3.8/site-packages/datadog_lambda/patch.py", line 133, in _log_request
    _print_request_string(request)
  File "/opt/python/lib/python3.8/site-packages/datadog_lambda/patch.py", line 147, in _print_request_string
    data_dict = json.loads(data)
  File "/var/lang/lib/python3.8/json/__init__.py", line 343, in loads
    s = s.decode(detect_encoding(s), 'surrogatepass')
UnicodeDecodeError: 'utf-8' codec can't decode byte 0x9c in position 1: invalid start byte{"traces": [[{"trace_id": "XXXX", "parent_id": "XXXX", "span_id": "XXXX", "service": "aws.lambda", "resource": "integration-dev-http-error_python38", "name": "aws.lambda", "error": 0, "start": XXXX, "duration": XXXX, "meta": {"_dd.origin": "lambda", "runtime-id": "XXXX", "cold_start": "true", "function_arn": "arn:aws:lambda:us-east-1:601427279990:function:integration-dev-http-error_python38", "function_version": "$LATEST", "request_id": "XXXX", "resource_names": "integration-dev-http-error_python38", "datadog_lambda": "X.X.X", "dd_trace": "X.X.X", "function_trigger.event_source": "api-gateway", "function_trigger.event_source_arn": "arn:aws:apigateway:us-east-1::/restapis/wt6mne2s9k/stages/test", "http.method": "GET", "http.status_code": "200"}, "metrics": {"_dd.agent_psr": 1.0, "system.pid": XXXX, "_sampling_priority_v1": 1}, "type": "serverless"}, {"trace_id": "XXXX", "parent_id": "XXXX", "span_id": "XXXX", "service": "aws.lambda", "resource": "requests.request", "name": "requests.request", "error": 0, "start": XXXX, "duration": XXXX, "meta": {"_dd.origin": "lambda", "http.method": "GET", "http.url": "https://httpstat.us/400/", "http.status_code": "400"}, "metrics": {"_dd.measured": 1}, "type": "http"}, {"trace_id": "XXXX", "parent_id": "XXXX", "span_id": "XXXX", "service": "aws.lambda", "resource": "requests.request", "name": "requests.request", "error": 1, "start": XXXX, "duration": XXXX, "meta": {"_dd.origin": "lambda", "http.method": "POST", "http.url": "https://api.datadoghq.com/api/v1/distribution_points", "error.msg": "'utf-8' codec can't decode byte 0x9c in position 1: invalid start byte", "error.type": "builtins.UnicodeDecodeError", "error.stack": "Traceback (most recent call last):\n  File \"/opt/python/lib/python3.8/site-packages/ddtrace/contrib/requests/connection.py\", line 95, in _wrap_send\n    response = func(*args, **kwargs)\n  File \"/opt/python/lib/python3.8/site-packages/datadog_lambda/patch.py\", line 133, in _log_request\n    _print_request_string(request)\n  File \"/opt/python/lib/python3.8/site-packages/datadog_lambda/patch.py\", line 147, in _print_request_string\n    data_dict = json.loads(data)\n  File \"/var/lang/lib/python3.8/json/__init__.py\", line 343, in loads\n    s = s.decode(detect_encoding(s), 'surrogatepass')\nUnicodeDecodeError: 'utf-8' codec can't decode byte 0x9c in position 1: invalid start byte\n"}, "metrics": {"_dd.measured": 1}, "type": "http"}]]}
END RequestId: XXXX
REPORT RequestId: XXXX	Duration: XXXX ms	Billed Duration: XXXX ms	Memory Size: 1024 MB	Max Memory Used: XXXX MB	Init Duration: XXXX ms	
XRAY TraceId: XXXX	SegmentId: XXXX	Sampled: true	
START RequestId: XXXX Version: $LATEST
{"m": "aws.lambda.enhanced.invocations", "v": 1, "e": XXXX, "t": ["region:us-east-1", "account_id:XXXX", "functionname:integration-dev-http-error_python38", "resource:integration-dev-http-error_python38", "cold_start:false", "memorysize:1024", "runtime:python3.8", "datadog_lambda:vXX", "dd_lambda_layer:datadog-python38_2.XX.0"]}
HTTP GET https://httpstat.us/400/ Headers: ["Accept-Encoding:gzip, deflate", "Accept:*/*", "Connection:keep-alive", "User-Agent:python-requests/2.25.1", "x-datadog-parent-id:XXXX", "x-datadog-sampling-priority:1", "x-datadog-trace-id:XXXX"] Data: {}
2021-03-24 19:21:41.337 (-04:00)	518a970d-5ce1-4b8c-bc33-69557a1dbc49	[ERROR]	[dd.trace_id=1570300133264875885 dd.span_id=16413185363777480631]	Error flushing metrics and events
Traceback (most recent call last):
  File "/opt/python/lib/python3.8/site-packages/datadog/threadstats/base.py", line 343, in flush
    self.reporter.flush_distributions(dists)
  File "/opt/python/lib/python3.8/site-packages/datadog/threadstats/reporters.py", line 24, in flush_distributions
    api.Distribution.send(distributions, compress_payload=self.compress_payload)
  File "/opt/python/lib/python3.8/site-packages/datadog/api/distributions.py", line 42, in send
    return super(Distribution, cls).send(
  File "/opt/python/lib/python3.8/site-packages/datadog/api/resources.py", line 82, in send
    return APIClient.submit(
  File "/opt/python/lib/python3.8/site-packages/datadog/api/api_client.py", line 162, in submit
    result = cls._get_http_client().request(
  File "/opt/python/lib/python3.8/site-packages/datadog/api/http_client.py", line 96, in request
    result = cls._session.request(
  File "/opt/python/lib/python3.8/site-packages/requests/sessions.py", line 542, in request
    resp = self.send(prep, **send_kwargs)
  File "/opt/python/lib/python3.8/site-packages/ddtrace/contrib/requests/connection.py", line 95, in _wrap_send
    response = func(*args, **kwargs)
  File "/opt/python/lib/python3.8/site-packages/datadog_lambda/patch.py", line 133, in _log_request
    _print_request_string(request)
  File "/opt/python/lib/python3.8/site-packages/datadog_lambda/patch.py", line 147, in _print_request_string
    data_dict = json.loads(data)
  File "/var/lang/lib/python3.8/json/__init__.py", line 343, in loads
    s = s.decode(detect_encoding(s), 'surrogatepass')
UnicodeDecodeError: 'utf-8' codec can't decode byte 0x9c in position 1: invalid start byte{"traces": [[{"trace_id": "XXXX", "parent_id": "XXXX", "span_id": "XXXX", "service": "aws.lambda", "resource": "integration-dev-http-error_python38", "name": "aws.lambda", "error": 0, "start": XXXX, "duration": XXXX, "meta": {"_dd.origin": "lambda", "runtime-id": "XXXX", "cold_start": "false", "function_arn": "arn:aws:lambda:us-east-1:601427279990:function:integration-dev-http-error_python38", "function_version": "$LATEST", "request_id": "XXXX", "resource_names": "integration-dev-http-error_python38", "datadog_lambda": "X.X.X", "dd_trace": "X.X.X", "function_trigger.event_source": "sns", "function_trigger.event_source_arn": "arn:aws:sns:us-east-2:123456789012:sns-lambda"}, "metrics": {"_dd.agent_psr": 1.0, "system.pid": XXXX, "_sampling_priority_v1": 1}, "type": "serverless"}, {"trace_id": "XXXX", "parent_id": "XXXX", "span_id": "XXXX", "service": "aws.lambda", "resource": "requests.request", "name": "requests.request", "error": 0, "start": XXXX, "duration": XXXX, "meta": {"_dd.origin": "lambda", "http.method": "GET", "http.url": "https://httpstat.us/400/", "http.status_code": "400"}, "metrics": {"_dd.measured": 1}, "type": "http"}, {"trace_id": "XXXX", "parent_id": "XXXX", "span_id": "XXXX", "service": "aws.lambda", "resource": "requests.request", "name": "requests.request", "error": 1, "start": XXXX, "duration": XXXX, "meta": {"_dd.origin": "lambda", "http.method": "POST", "http.url": "https://api.datadoghq.com/api/v1/distribution_points", "error.msg": "'utf-8' codec can't decode byte 0x9c in position 1: invalid start byte", "error.type": "builtins.UnicodeDecodeError", "error.stack": "Traceback (most recent call last):\n  File \"/opt/python/lib/python3.8/site-packages/ddtrace/contrib/requests/connection.py\", line 95, in _wrap_send\n    response = func(*args, **kwargs)\n  File \"/opt/python/lib/python3.8/site-packages/datadog_lambda/patch.py\", line 133, in _log_request\n    _print_request_string(request)\n  File \"/opt/python/lib/python3.8/site-packages/datadog_lambda/patch.py\", line 147, in _print_request_string\n    data_dict = json.loads(data)\n  File \"/var/lang/lib/python3.8/json/__init__.py\", line 343, in loads\n    s = s.decode(detect_encoding(s), 'surrogatepass')\nUnicodeDecodeError: 'utf-8' codec can't decode byte 0x9c in position 1: invalid start byte\n"}, "metrics": {"_dd.measured": 1}, "type": "http"}]]}
END RequestId: XXXX
REPORT RequestId: XXXX	Duration: XXXX ms	Billed Duration: XXXX ms	Memory Size: 1024 MB	Max Memory Used: XXXX MB	
XRAY TraceId: XXXX	SegmentId: XXXX	Sampled: true	
START RequestId: XXXX Version: $LATEST
{"m": "aws.lambda.enhanced.invocations", "v": 1, "e": XXXX, "t": ["region:us-east-1", "account_id:XXXX", "functionname:integration-dev-http-error_python38", "resource:integration-dev-http-error_python38", "cold_start:false", "memorysize:1024", "runtime:python3.8", "datadog_lambda:vXX", "dd_lambda_layer:datadog-python38_2.XX.0"]}
HTTP GET https://httpstat.us/400/ Headers: ["Accept-Encoding:gzip, deflate", "Accept:*/*", "Connection:keep-alive", "User-Agent:python-requests/2.25.1", "x-datadog-parent-id:XXXX", "x-datadog-sampling-priority:1", "x-datadog-trace-id:XXXX"] Data: {}
2021-03-24 19:21:43.160 (-04:00)	1c629eda-c29f-4d46-a8f2-63f12949cab2	[ERROR]	[dd.trace_id=666 dd.span_id=10946584854586957938]	Error flushing metrics and events
Traceback (most recent call last):
  File "/opt/python/lib/python3.8/site-packages/datadog/threadstats/base.py", line 343, in flush
    self.reporter.flush_distributions(dists)
  File "/opt/python/lib/python3.8/site-packages/datadog/threadstats/reporters.py", line 24, in flush_distributions
    api.Distribution.send(distributions, compress_payload=self.compress_payload)
  File "/opt/python/lib/python3.8/site-packages/datadog/api/distributions.py", line 42, in send
    return super(Distribution, cls).send(
  File "/opt/python/lib/python3.8/site-packages/datadog/api/resources.py", line 82, in send
    return APIClient.submit(
  File "/opt/python/lib/python3.8/site-packages/datadog/api/api_client.py", line 162, in submit
    result = cls._get_http_client().request(
  File "/opt/python/lib/python3.8/site-packages/datadog/api/http_client.py", line 96, in request
    result = cls._session.request(
  File "/opt/python/lib/python3.8/site-packages/requests/sessions.py", line 542, in request
    resp = self.send(prep, **send_kwargs)
  File "/opt/python/lib/python3.8/site-packages/ddtrace/contrib/requests/connection.py", line 95, in _wrap_send
    response = func(*args, **kwargs)
  File "/opt/python/lib/python3.8/site-packages/datadog_lambda/patch.py", line 133, in _log_request
    _print_request_string(request)
  File "/opt/python/lib/python3.8/site-packages/datadog_lambda/patch.py", line 147, in _print_request_string
    data_dict = json.loads(data)
  File "/var/lang/lib/python3.8/json/__init__.py", line 343, in loads
    s = s.decode(detect_encoding(s), 'surrogatepass')
UnicodeDecodeError: 'utf-8' codec can't decode byte 0x9c in position 1: invalid start byte{"traces": [[{"trace_id": "XXXX", "parent_id": "XXXX", "span_id": "XXXX", "service": "aws.lambda", "resource": "integration-dev-http-error_python38", "name": "aws.lambda", "error": 0, "start": XXXX, "duration": XXXX, "meta": {"_dd.origin": "lambda", "runtime-id": "XXXX", "cold_start": "false", "function_arn": "arn:aws:lambda:us-east-1:601427279990:function:integration-dev-http-error_python38", "function_version": "$LATEST", "request_id": "XXXX", "resource_names": "integration-dev-http-error_python38", "datadog_lambda": "X.X.X", "dd_trace": "X.X.X", "function_trigger.event_source": "sqs", "function_trigger.event_source_arn": "arn:aws:sqs:us-east-2:123456789012:my-queue"}, "metrics": {"system.pid": XXXX, "_sampling_priority_v1": 1}, "type": "serverless"}, {"trace_id": "XXXX", "parent_id": "XXXX", "span_id": "XXXX", "service": "aws.lambda", "resource": "requests.request", "name": "requests.request", "error": 0, "start": XXXX, "duration": XXXX, "meta": {"_dd.origin": "lambda", "http.method": "GET", "http.url": "https://httpstat.us/400/", "http.status_code": "400"}, "metrics": {"_dd.measured": 1}, "type": "http"}, {"trace_id": "XXXX", "parent_id": "XXXX", "span_id": "XXXX", "service": "aws.lambda", "resource": "requests.request", "name": "requests.request", "error": 1, "start": XXXX, "duration": XXXX, "meta": {"_dd.origin": "lambda", "http.method": "POST", "http.url": "https://api.datadoghq.com/api/v1/distribution_points", "error.msg": "'utf-8' codec can't decode byte 0x9c in position 1: invalid start byte", "error.type": "builtins.UnicodeDecodeError", "error.stack": "Traceback (most recent call last):\n  File \"/opt/python/lib/python3.8/site-packages/ddtrace/contrib/requests/connection.py\", line 95, in _wrap_send\n    response = func(*args, **kwargs)\n  File \"/opt/python/lib/python3.8/site-packages/datadog_lambda/patch.py\", line 133, in _log_request\n    _print_request_string(request)\n  File \"/opt/python/lib/python3.8/site-packages/datadog_lambda/patch.py\", line 147, in _print_request_string\n    data_dict = json.loads(data)\n  File \"/var/lang/lib/python3.8/json/__init__.py\", line 343, in loads\n    s = s.decode(detect_encoding(s), 'surrogatepass')\nUnicodeDecodeError: 'utf-8' codec can't decode byte 0x9c in position 1: invalid start byte\n"}, "metrics": {"_dd.measured": 1}, "type": "http"}]]}
END RequestId: XXXX
REPORT RequestId: XXXX	Duration: XXXX ms	Billed Duration: XXXX ms	Memory Size: 1024 MB	Max Memory Used: XXXX MB	
XRAY TraceId: XXXX	SegmentId: XXXX	Sampled: true	
