/var/runtime/botocore/vendored/requests/__init__.py:91: RequestsDependencyWarning: urllib3 (1.26.4) or chardet (4.0.0) doesn't match a supported version!
RequestsDependencyWarning)
START RequestId: XXXX Version: $LATEST
{"e": XXXX, "m": "aws.lambda.enhanced.invocations", "t": ["region:us-east-1", "account_id:XXXX", "functionname:integration-dev-http-error_python27", "resource:integration-dev-http-error_python27", "cold_start:true", "memorysize:1024", "runtime:python2.7", "datadog_lambda:vXX", "dd_lambda_layer:datadog-python27_2.XX.0"], "v": 1}
HTTP GET https://httpstat.us/400/ Headers: ["Accept-Encoding:gzip, deflate", "Accept:*/*", "Connection:keep-alive", "User-Agent:python-requests/2.25.1", "x-datadog-parent-id:XXXX", "x-datadog-sampling-priority:1", "x-datadog-trace-id:XXXX"] Data: {}
2021-03-24 18:59:46.789 (-04:00)	e530998a-44ca-4189-b71e-addda5da68b9	[ERROR]	[dd.trace_id=3340892274166087800 dd.span_id=14961159637560740840]	Error flushing metrics and events
Traceback (most recent call last):
  File "/opt/python/lib/python2.7/site-packages/datadog/threadstats/base.py", line 343, in flush
    self.reporter.flush_distributions(dists)
  File "/opt/python/lib/python2.7/site-packages/datadog/threadstats/reporters.py", line 24, in flush_distributions
    api.Distribution.send(distributions, compress_payload=self.compress_payload)
  File "/opt/python/lib/python2.7/site-packages/datadog/api/distributions.py", line 43, in send
    attach_host_name=attach_host_name, compress_payload=compress_payload, **series_dict
  File "/opt/python/lib/python2.7/site-packages/datadog/api/resources.py", line 88, in send
    compress_payload=compress_payload
  File "/opt/python/lib/python2.7/site-packages/datadog/api/api_client.py", line 166, in submit
    proxies=_proxies, verify=_cacert
  File "/opt/python/lib/python2.7/site-packages/datadog/api/http_client.py", line 100, in request
    proxies=proxies, verify=verify)
  File "/opt/python/lib/python2.7/site-packages/requests/sessions.py", line 542, in request
    resp = self.send(prep, **send_kwargs)
  File "/opt/python/lib/python2.7/site-packages/ddtrace/contrib/requests/connection.py", line 95, in _wrap_send
    response = func(*args, **kwargs)
  File "/opt/python/lib/python2.7/site-packages/datadog_lambda/patch.py", line 133, in _log_request
    _print_request_string(request)
  File "/opt/python/lib/python2.7/site-packages/datadog_lambda/patch.py", line 147, in _print_request_string
    data_dict = json.loads(data)
  File "/usr/lib64/python2.7/json/__init__.py", line 339, in loads
    return _default_decoder.decode(s)
  File "/usr/lib64/python2.7/json/decoder.py", line 364, in decode
    obj, end = self.raw_decode(s, idx=_w(s, 0).end())
  File "/usr/lib64/python2.7/json/decoder.py", line 382, in raw_decode
    raise ValueError("No JSON object could be decoded")
ValueError: No JSON object could be decoded{"traces": [[{"resource": "integration-dev-http-error_python27", "name": "aws.lambda", "service": "aws.lambda", "start": XXXX, "trace_id": "XXXX", "metrics": {"_sampling_priority_v1": 1, "system.pid": XXXX, "_dd.agent_psr": 1.0}, "parent_id": "XXXX", "meta": {"http.method": "GET", "runtime-id": "XXXX", "request_id": "XXXX", "function_trigger.event_source": "api-gateway", "cold_start": "true", "datadog_lambda": "X.X.X", "function_arn": "arn:aws:lambda:us-east-1:601427279990:function:integration-dev-http-error_python27", "dd_trace": "X.X.X", "_dd.origin": "lambda", "http.status_code": "200", "resource_names": "integration-dev-http-error_python27", "function_trigger.event_source_arn": "arn:aws:apigateway:us-east-1::/restapis/wt6mne2s9k/stages/test", "function_version": "$LATEST"}, "error": 0, "duration": XXXX, "type": "serverless", "span_id": "XXXX"}, {"resource": "requests.request", "name": "requests.request", "service": "aws.lambda", "start": XXXX, "trace_id": "XXXX", "metrics": {"_dd.measured": 1}, "parent_id": "XXXX", "meta": {"http.status_code": "400", "http.url": "https://httpstat.us/400/", "_dd.origin": "lambda", "http.method": "GET"}, "error": 0, "duration": XXXX, "type": "http", "span_id": "XXXX"}, {"resource": "requests.request", "name": "requests.request", "service": "aws.lambda", "start": XXXX, "trace_id": "XXXX", "metrics": {"_dd.measured": 1}, "parent_id": "XXXX", "meta": {"http.method": "POST", "http.url": "https://api.datadoghq.com/api/v1/distribution_points", "error.type": "exceptions.ValueError", "_dd.origin": "lambda", "error.msg": "No JSON object could be decoded", "error.stack": "Traceback (most recent call last):\n  File \"/opt/python/lib/python2.7/site-packages/ddtrace/contrib/requests/connection.py\", line 95, in _wrap_send\n    response = func(*args, **kwargs)\n  File \"/opt/python/lib/python2.7/site-packages/datadog_lambda/patch.py\", line 133, in _log_request\n    _print_request_string(request)\n  File \"/opt/python/lib/python2.7/site-packages/datadog_lambda/patch.py\", line 147, in _print_request_string\n    data_dict = json.loads(data)\n  File \"/usr/lib64/python2.7/json/__init__.py\", line 339, in loads\n    return _default_decoder.decode(s)\n  File \"/usr/lib64/python2.7/json/decoder.py\", line 364, in decode\n    obj, end = self.raw_decode(s, idx=_w(s, 0).end())\n  File \"/usr/lib64/python2.7/json/decoder.py\", line 382, in raw_decode\n    raise ValueError(\"No JSON object could be decoded\")\nValueError: No JSON object could be decoded\n"}, "error": 1, "duration": XXXX, "type": "http", "span_id": "XXXX"}]]}
END RequestId: XXXX
REPORT RequestId: XXXX	Duration: XXXX ms	Billed Duration: XXXX ms	Memory Size: 1024 MB	Max Memory Used: XXXX MB	Init Duration: XXXX ms	
XRAY TraceId: XXXX	SegmentId: XXXX	Sampled: true	
START RequestId: XXXX Version: $LATEST
{"e": XXXX, "m": "aws.lambda.enhanced.invocations", "t": ["region:us-east-1", "account_id:XXXX", "functionname:integration-dev-http-error_python27", "resource:integration-dev-http-error_python27", "cold_start:false", "memorysize:1024", "runtime:python2.7", "datadog_lambda:vXX", "dd_lambda_layer:datadog-python27_2.XX.0"], "v": 1}
HTTP GET https://httpstat.us/400/ Headers: ["Accept-Encoding:gzip, deflate", "Accept:*/*", "Connection:keep-alive", "User-Agent:python-requests/2.25.1", "x-datadog-parent-id:XXXX", "x-datadog-sampling-priority:1", "x-datadog-trace-id:XXXX"] Data: {}
2021-03-24 18:59:48.401 (-04:00)	be78d0c0-69a5-4c03-bc2f-d51176c9fa38	[ERROR]	[dd.trace_id=9937290474531325641 dd.span_id=16987596749041931562]	Error flushing metrics and events
Traceback (most recent call last):
  File "/opt/python/lib/python2.7/site-packages/datadog/threadstats/base.py", line 343, in flush
    self.reporter.flush_distributions(dists)
  File "/opt/python/lib/python2.7/site-packages/datadog/threadstats/reporters.py", line 24, in flush_distributions
    api.Distribution.send(distributions, compress_payload=self.compress_payload)
  File "/opt/python/lib/python2.7/site-packages/datadog/api/distributions.py", line 43, in send
    attach_host_name=attach_host_name, compress_payload=compress_payload, **series_dict
  File "/opt/python/lib/python2.7/site-packages/datadog/api/resources.py", line 88, in send
    compress_payload=compress_payload
  File "/opt/python/lib/python2.7/site-packages/datadog/api/api_client.py", line 166, in submit
    proxies=_proxies, verify=_cacert
  File "/opt/python/lib/python2.7/site-packages/datadog/api/http_client.py", line 100, in request
    proxies=proxies, verify=verify)
  File "/opt/python/lib/python2.7/site-packages/requests/sessions.py", line 542, in request
    resp = self.send(prep, **send_kwargs)
  File "/opt/python/lib/python2.7/site-packages/ddtrace/contrib/requests/connection.py", line 95, in _wrap_send
    response = func(*args, **kwargs)
  File "/opt/python/lib/python2.7/site-packages/datadog_lambda/patch.py", line 133, in _log_request
    _print_request_string(request)
  File "/opt/python/lib/python2.7/site-packages/datadog_lambda/patch.py", line 147, in _print_request_string
    data_dict = json.loads(data)
  File "/usr/lib64/python2.7/json/__init__.py", line 339, in loads
    return _default_decoder.decode(s)
  File "/usr/lib64/python2.7/json/decoder.py", line 364, in decode
    obj, end = self.raw_decode(s, idx=_w(s, 0).end())
  File "/usr/lib64/python2.7/json/decoder.py", line 382, in raw_decode
    raise ValueError("No JSON object could be decoded")
ValueError: No JSON object could be decoded{"traces": [[{"resource": "integration-dev-http-error_python27", "name": "aws.lambda", "service": "aws.lambda", "start": XXXX, "trace_id": "XXXX", "metrics": {"_sampling_priority_v1": 1, "system.pid": XXXX, "_dd.agent_psr": 1.0}, "parent_id": "XXXX", "meta": {"runtime-id": "XXXX", "request_id": "XXXX", "function_trigger.event_source": "sns", "cold_start": "false", "datadog_lambda": "X.X.X", "function_arn": "arn:aws:lambda:us-east-1:601427279990:function:integration-dev-http-error_python27", "dd_trace": "X.X.X", "_dd.origin": "lambda", "resource_names": "integration-dev-http-error_python27", "function_trigger.event_source_arn": "arn:aws:sns:us-east-2:123456789012:sns-lambda", "function_version": "$LATEST"}, "error": 0, "duration": XXXX, "type": "serverless", "span_id": "XXXX"}, {"resource": "requests.request", "name": "requests.request", "service": "aws.lambda", "start": XXXX, "trace_id": "XXXX", "metrics": {"_dd.measured": 1}, "parent_id": "XXXX", "meta": {"http.status_code": "400", "http.url": "https://httpstat.us/400/", "_dd.origin": "lambda", "http.method": "GET"}, "error": 0, "duration": XXXX, "type": "http", "span_id": "XXXX"}, {"resource": "requests.request", "name": "requests.request", "service": "aws.lambda", "start": XXXX, "trace_id": "XXXX", "metrics": {"_dd.measured": 1}, "parent_id": "XXXX", "meta": {"http.method": "POST", "http.url": "https://api.datadoghq.com/api/v1/distribution_points", "error.type": "exceptions.ValueError", "_dd.origin": "lambda", "error.msg": "No JSON object could be decoded", "error.stack": "Traceback (most recent call last):\n  File \"/opt/python/lib/python2.7/site-packages/ddtrace/contrib/requests/connection.py\", line 95, in _wrap_send\n    response = func(*args, **kwargs)\n  File \"/opt/python/lib/python2.7/site-packages/datadog_lambda/patch.py\", line 133, in _log_request\n    _print_request_string(request)\n  File \"/opt/python/lib/python2.7/site-packages/datadog_lambda/patch.py\", line 147, in _print_request_string\n    data_dict = json.loads(data)\n  File \"/usr/lib64/python2.7/json/__init__.py\", line 339, in loads\n    return _default_decoder.decode(s)\n  File \"/usr/lib64/python2.7/json/decoder.py\", line 364, in decode\n    obj, end = self.raw_decode(s, idx=_w(s, 0).end())\n  File \"/usr/lib64/python2.7/json/decoder.py\", line 382, in raw_decode\n    raise ValueError(\"No JSON object could be decoded\")\nValueError: No JSON object could be decoded\n"}, "error": 1, "duration": XXXX, "type": "http", "span_id": "XXXX"}]]}
END RequestId: XXXX
REPORT RequestId: XXXX	Duration: XXXX ms	Billed Duration: XXXX ms	Memory Size: 1024 MB	Max Memory Used: XXXX MB	
XRAY TraceId: XXXX	SegmentId: XXXX	Sampled: true	
START RequestId: XXXX Version: $LATEST
{"e": XXXX, "m": "aws.lambda.enhanced.invocations", "t": ["region:us-east-1", "account_id:XXXX", "functionname:integration-dev-http-error_python27", "resource:integration-dev-http-error_python27", "cold_start:false", "memorysize:1024", "runtime:python2.7", "datadog_lambda:vXX", "dd_lambda_layer:datadog-python27_2.XX.0"], "v": 1}
HTTP GET https://httpstat.us/400/ Headers: ["Accept-Encoding:gzip, deflate", "Accept:*/*", "Connection:keep-alive", "User-Agent:python-requests/2.25.1", "x-datadog-parent-id:XXXX", "x-datadog-sampling-priority:1", "x-datadog-trace-id:XXXX"] Data: {}
2021-03-24 18:59:49.928 (-04:00)	06bd9779-029e-4e06-b053-f2504452e7ac	[ERROR]	[dd.trace_id=666 dd.span_id=11324129443624142947]	Error flushing metrics and events
Traceback (most recent call last):
  File "/opt/python/lib/python2.7/site-packages/datadog/threadstats/base.py", line 343, in flush
    self.reporter.flush_distributions(dists)
  File "/opt/python/lib/python2.7/site-packages/datadog/threadstats/reporters.py", line 24, in flush_distributions
    api.Distribution.send(distributions, compress_payload=self.compress_payload)
  File "/opt/python/lib/python2.7/site-packages/datadog/api/distributions.py", line 43, in send
    attach_host_name=attach_host_name, compress_payload=compress_payload, **series_dict
  File "/opt/python/lib/python2.7/site-packages/datadog/api/resources.py", line 88, in send
    compress_payload=compress_payload
  File "/opt/python/lib/python2.7/site-packages/datadog/api/api_client.py", line 166, in submit
    proxies=_proxies, verify=_cacert
  File "/opt/python/lib/python2.7/site-packages/datadog/api/http_client.py", line 100, in request
    proxies=proxies, verify=verify)
  File "/opt/python/lib/python2.7/site-packages/requests/sessions.py", line 542, in request
    resp = self.send(prep, **send_kwargs)
  File "/opt/python/lib/python2.7/site-packages/ddtrace/contrib/requests/connection.py", line 95, in _wrap_send
    response = func(*args, **kwargs)
  File "/opt/python/lib/python2.7/site-packages/datadog_lambda/patch.py", line 133, in _log_request
    _print_request_string(request)
  File "/opt/python/lib/python2.7/site-packages/datadog_lambda/patch.py", line 147, in _print_request_string
    data_dict = json.loads(data)
  File "/usr/lib64/python2.7/json/__init__.py", line 339, in loads
    return _default_decoder.decode(s)
  File "/usr/lib64/python2.7/json/decoder.py", line 364, in decode
    obj, end = self.raw_decode(s, idx=_w(s, 0).end())
  File "/usr/lib64/python2.7/json/decoder.py", line 382, in raw_decode
    raise ValueError("No JSON object could be decoded")
ValueError: No JSON object could be decoded{"traces": [[{"resource": "integration-dev-http-error_python27", "name": "aws.lambda", "service": "aws.lambda", "start": XXXX, "trace_id": "XXXX", "metrics": {"_sampling_priority_v1": 1, "system.pid": XXXX}, "parent_id": "XXXX", "meta": {"runtime-id": "XXXX", "request_id": "XXXX", "function_trigger.event_source": "sqs", "cold_start": "false", "datadog_lambda": "X.X.X", "function_arn": "arn:aws:lambda:us-east-1:601427279990:function:integration-dev-http-error_python27", "dd_trace": "X.X.X", "_dd.origin": "lambda", "resource_names": "integration-dev-http-error_python27", "function_trigger.event_source_arn": "arn:aws:sqs:us-east-2:123456789012:my-queue", "function_version": "$LATEST"}, "error": 0, "duration": XXXX, "type": "serverless", "span_id": "XXXX"}, {"resource": "requests.request", "name": "requests.request", "service": "aws.lambda", "start": XXXX, "trace_id": "XXXX", "metrics": {"_dd.measured": 1}, "parent_id": "XXXX", "meta": {"http.status_code": "400", "http.url": "https://httpstat.us/400/", "_dd.origin": "lambda", "http.method": "GET"}, "error": 0, "duration": XXXX, "type": "http", "span_id": "XXXX"}, {"resource": "requests.request", "name": "requests.request", "service": "aws.lambda", "start": XXXX, "trace_id": "XXXX", "metrics": {"_dd.measured": 1}, "parent_id": "XXXX", "meta": {"http.method": "POST", "http.url": "https://api.datadoghq.com/api/v1/distribution_points", "error.type": "exceptions.ValueError", "_dd.origin": "lambda", "error.msg": "No JSON object could be decoded", "error.stack": "Traceback (most recent call last):\n  File \"/opt/python/lib/python2.7/site-packages/ddtrace/contrib/requests/connection.py\", line 95, in _wrap_send\n    response = func(*args, **kwargs)\n  File \"/opt/python/lib/python2.7/site-packages/datadog_lambda/patch.py\", line 133, in _log_request\n    _print_request_string(request)\n  File \"/opt/python/lib/python2.7/site-packages/datadog_lambda/patch.py\", line 147, in _print_request_string\n    data_dict = json.loads(data)\n  File \"/usr/lib64/python2.7/json/__init__.py\", line 339, in loads\n    return _default_decoder.decode(s)\n  File \"/usr/lib64/python2.7/json/decoder.py\", line 364, in decode\n    obj, end = self.raw_decode(s, idx=_w(s, 0).end())\n  File \"/usr/lib64/python2.7/json/decoder.py\", line 382, in raw_decode\n    raise ValueError(\"No JSON object could be decoded\")\nValueError: No JSON object could be decoded\n"}, "error": 1, "duration": XXXX, "type": "http", "span_id": "XXXX"}]]}
END RequestId: XXXX
REPORT RequestId: XXXX	Duration: XXXX ms	Billed Duration: XXXX ms	Memory Size: 1024 MB	Max Memory Used: XXXX MB	
XRAY TraceId: XXXX	SegmentId: XXXX	Sampled: true	
/var/runtime/botocore/vendored/requests/__init__.py:91: RequestsDependencyWarning: urllib3 (1.26.4) or chardet (4.0.0) doesn't match a supported version!
RequestsDependencyWarning)
/var/runtime/botocore/vendored/requests/__init__.py:91: RequestsDependencyWarning: urllib3 (1.26.4) or chardet (4.0.0) doesn't match a supported version!
RequestsDependencyWarning)
START RequestId: XXXX Version: $LATEST
{"e": XXXX, "m": "aws.lambda.enhanced.invocations", "t": ["region:us-east-1", "account_id:XXXX", "functionname:integration-dev-http-error_python27", "resource:integration-dev-http-error_python27", "cold_start:true", "memorysize:1024", "runtime:python2.7", "datadog_lambda:vXX", "dd_lambda_layer:datadog-python27_2.XX.0"], "v": 1}
HTTP GET https://httpstat.us/400/ Headers: ["Accept-Encoding:gzip, deflate", "Accept:*/*", "Connection:keep-alive", "User-Agent:python-requests/2.25.1", "x-datadog-parent-id:XXXX", "x-datadog-sampling-priority:1", "x-datadog-trace-id:XXXX"] Data: {}
2021-03-24 19:21:21.858 (-04:00)	1fdcbb07-b106-47c5-94cb-b612fe6973eb	[ERROR]	[dd.trace_id=18198273682568508671 dd.span_id=7823323511500165047]	Error flushing metrics and events
Traceback (most recent call last):
  File "/opt/python/lib/python2.7/site-packages/datadog/threadstats/base.py", line 343, in flush
    self.reporter.flush_distributions(dists)
  File "/opt/python/lib/python2.7/site-packages/datadog/threadstats/reporters.py", line 24, in flush_distributions
    api.Distribution.send(distributions, compress_payload=self.compress_payload)
  File "/opt/python/lib/python2.7/site-packages/datadog/api/distributions.py", line 43, in send
    attach_host_name=attach_host_name, compress_payload=compress_payload, **series_dict
  File "/opt/python/lib/python2.7/site-packages/datadog/api/resources.py", line 88, in send
    compress_payload=compress_payload
  File "/opt/python/lib/python2.7/site-packages/datadog/api/api_client.py", line 166, in submit
    proxies=_proxies, verify=_cacert
  File "/opt/python/lib/python2.7/site-packages/datadog/api/http_client.py", line 100, in request
    proxies=proxies, verify=verify)
  File "/opt/python/lib/python2.7/site-packages/requests/sessions.py", line 542, in request
    resp = self.send(prep, **send_kwargs)
  File "/opt/python/lib/python2.7/site-packages/ddtrace/contrib/requests/connection.py", line 95, in _wrap_send
    response = func(*args, **kwargs)
  File "/opt/python/lib/python2.7/site-packages/datadog_lambda/patch.py", line 133, in _log_request
    _print_request_string(request)
  File "/opt/python/lib/python2.7/site-packages/datadog_lambda/patch.py", line 147, in _print_request_string
    data_dict = json.loads(data)
  File "/usr/lib64/python2.7/json/__init__.py", line 339, in loads
    return _default_decoder.decode(s)
  File "/usr/lib64/python2.7/json/decoder.py", line 364, in decode
    obj, end = self.raw_decode(s, idx=_w(s, 0).end())
  File "/usr/lib64/python2.7/json/decoder.py", line 382, in raw_decode
    raise ValueError("No JSON object could be decoded")
ValueError: No JSON object could be decoded{"traces": [[{"resource": "integration-dev-http-error_python27", "name": "aws.lambda", "service": "aws.lambda", "start": XXXX, "trace_id": "XXXX", "metrics": {"_sampling_priority_v1": 1, "system.pid": XXXX, "_dd.agent_psr": 1.0}, "parent_id": "XXXX", "meta": {"http.method": "GET", "runtime-id": "XXXX", "request_id": "XXXX", "function_trigger.event_source": "api-gateway", "cold_start": "true", "datadog_lambda": "X.X.X", "function_arn": "arn:aws:lambda:us-east-1:601427279990:function:integration-dev-http-error_python27", "dd_trace": "X.X.X", "_dd.origin": "lambda", "http.status_code": "200", "resource_names": "integration-dev-http-error_python27", "function_trigger.event_source_arn": "arn:aws:apigateway:us-east-1::/restapis/wt6mne2s9k/stages/test", "function_version": "$LATEST"}, "error": 0, "duration": XXXX, "type": "serverless", "span_id": "XXXX"}, {"resource": "requests.request", "name": "requests.request", "service": "aws.lambda", "start": XXXX, "trace_id": "XXXX", "metrics": {"_dd.measured": 1}, "parent_id": "XXXX", "meta": {"http.status_code": "400", "http.url": "https://httpstat.us/400/", "_dd.origin": "lambda", "http.method": "GET"}, "error": 0, "duration": XXXX, "type": "http", "span_id": "XXXX"}, {"resource": "requests.request", "name": "requests.request", "service": "aws.lambda", "start": XXXX, "trace_id": "XXXX", "metrics": {"_dd.measured": 1}, "parent_id": "XXXX", "meta": {"http.method": "POST", "http.url": "https://api.datadoghq.com/api/v1/distribution_points", "error.type": "exceptions.ValueError", "_dd.origin": "lambda", "error.msg": "No JSON object could be decoded", "error.stack": "Traceback (most recent call last):\n  File \"/opt/python/lib/python2.7/site-packages/ddtrace/contrib/requests/connection.py\", line 95, in _wrap_send\n    response = func(*args, **kwargs)\n  File \"/opt/python/lib/python2.7/site-packages/datadog_lambda/patch.py\", line 133, in _log_request\n    _print_request_string(request)\n  File \"/opt/python/lib/python2.7/site-packages/datadog_lambda/patch.py\", line 147, in _print_request_string\n    data_dict = json.loads(data)\n  File \"/usr/lib64/python2.7/json/__init__.py\", line 339, in loads\n    return _default_decoder.decode(s)\n  File \"/usr/lib64/python2.7/json/decoder.py\", line 364, in decode\n    obj, end = self.raw_decode(s, idx=_w(s, 0).end())\n  File \"/usr/lib64/python2.7/json/decoder.py\", line 382, in raw_decode\n    raise ValueError(\"No JSON object could be decoded\")\nValueError: No JSON object could be decoded\n"}, "error": 1, "duration": XXXX, "type": "http", "span_id": "XXXX"}]]}
END RequestId: XXXX
REPORT RequestId: XXXX	Duration: XXXX ms	Billed Duration: XXXX ms	Memory Size: 1024 MB	Max Memory Used: XXXX MB	Init Duration: XXXX ms	
XRAY TraceId: XXXX	SegmentId: XXXX	Sampled: true	
START RequestId: XXXX Version: $LATEST
{"e": XXXX, "m": "aws.lambda.enhanced.invocations", "t": ["region:us-east-1", "account_id:XXXX", "functionname:integration-dev-http-error_python27", "resource:integration-dev-http-error_python27", "cold_start:false", "memorysize:1024", "runtime:python2.7", "datadog_lambda:vXX", "dd_lambda_layer:datadog-python27_2.XX.0"], "v": 1}
HTTP GET https://httpstat.us/400/ Headers: ["Accept-Encoding:gzip, deflate", "Accept:*/*", "Connection:keep-alive", "User-Agent:python-requests/2.25.1", "x-datadog-parent-id:XXXX", "x-datadog-sampling-priority:1", "x-datadog-trace-id:XXXX"] Data: {}
2021-03-24 19:21:23.446 (-04:00)	5c96b333-a600-4cc7-a7a5-c0310d579c74	[ERROR]	[dd.trace_id=8140581649282976687 dd.span_id=16095869216501870207]	Error flushing metrics and events
Traceback (most recent call last):
  File "/opt/python/lib/python2.7/site-packages/datadog/threadstats/base.py", line 343, in flush
    self.reporter.flush_distributions(dists)
  File "/opt/python/lib/python2.7/site-packages/datadog/threadstats/reporters.py", line 24, in flush_distributions
    api.Distribution.send(distributions, compress_payload=self.compress_payload)
  File "/opt/python/lib/python2.7/site-packages/datadog/api/distributions.py", line 43, in send
    attach_host_name=attach_host_name, compress_payload=compress_payload, **series_dict
  File "/opt/python/lib/python2.7/site-packages/datadog/api/resources.py", line 88, in send
    compress_payload=compress_payload
  File "/opt/python/lib/python2.7/site-packages/datadog/api/api_client.py", line 166, in submit
    proxies=_proxies, verify=_cacert
  File "/opt/python/lib/python2.7/site-packages/datadog/api/http_client.py", line 100, in request
    proxies=proxies, verify=verify)
  File "/opt/python/lib/python2.7/site-packages/requests/sessions.py", line 542, in request
    resp = self.send(prep, **send_kwargs)
  File "/opt/python/lib/python2.7/site-packages/ddtrace/contrib/requests/connection.py", line 95, in _wrap_send
    response = func(*args, **kwargs)
  File "/opt/python/lib/python2.7/site-packages/datadog_lambda/patch.py", line 133, in _log_request
    _print_request_string(request)
  File "/opt/python/lib/python2.7/site-packages/datadog_lambda/patch.py", line 147, in _print_request_string
    data_dict = json.loads(data)
  File "/usr/lib64/python2.7/json/__init__.py", line 339, in loads
    return _default_decoder.decode(s)
  File "/usr/lib64/python2.7/json/decoder.py", line 364, in decode
    obj, end = self.raw_decode(s, idx=_w(s, 0).end())
  File "/usr/lib64/python2.7/json/decoder.py", line 382, in raw_decode
    raise ValueError("No JSON object could be decoded")
ValueError: No JSON object could be decoded{"traces": [[{"resource": "integration-dev-http-error_python27", "name": "aws.lambda", "service": "aws.lambda", "start": XXXX, "trace_id": "XXXX", "metrics": {"_sampling_priority_v1": 1, "system.pid": XXXX, "_dd.agent_psr": 1.0}, "parent_id": "XXXX", "meta": {"runtime-id": "XXXX", "request_id": "XXXX", "function_trigger.event_source": "sns", "cold_start": "false", "datadog_lambda": "X.X.X", "function_arn": "arn:aws:lambda:us-east-1:601427279990:function:integration-dev-http-error_python27", "dd_trace": "X.X.X", "_dd.origin": "lambda", "resource_names": "integration-dev-http-error_python27", "function_trigger.event_source_arn": "arn:aws:sns:us-east-2:123456789012:sns-lambda", "function_version": "$LATEST"}, "error": 0, "duration": XXXX, "type": "serverless", "span_id": "XXXX"}, {"resource": "requests.request", "name": "requests.request", "service": "aws.lambda", "start": XXXX, "trace_id": "XXXX", "metrics": {"_dd.measured": 1}, "parent_id": "XXXX", "meta": {"http.status_code": "400", "http.url": "https://httpstat.us/400/", "_dd.origin": "lambda", "http.method": "GET"}, "error": 0, "duration": XXXX, "type": "http", "span_id": "XXXX"}, {"resource": "requests.request", "name": "requests.request", "service": "aws.lambda", "start": XXXX, "trace_id": "XXXX", "metrics": {"_dd.measured": 1}, "parent_id": "XXXX", "meta": {"http.method": "POST", "http.url": "https://api.datadoghq.com/api/v1/distribution_points", "error.type": "exceptions.ValueError", "_dd.origin": "lambda", "error.msg": "No JSON object could be decoded", "error.stack": "Traceback (most recent call last):\n  File \"/opt/python/lib/python2.7/site-packages/ddtrace/contrib/requests/connection.py\", line 95, in _wrap_send\n    response = func(*args, **kwargs)\n  File \"/opt/python/lib/python2.7/site-packages/datadog_lambda/patch.py\", line 133, in _log_request\n    _print_request_string(request)\n  File \"/opt/python/lib/python2.7/site-packages/datadog_lambda/patch.py\", line 147, in _print_request_string\n    data_dict = json.loads(data)\n  File \"/usr/lib64/python2.7/json/__init__.py\", line 339, in loads\n    return _default_decoder.decode(s)\n  File \"/usr/lib64/python2.7/json/decoder.py\", line 364, in decode\n    obj, end = self.raw_decode(s, idx=_w(s, 0).end())\n  File \"/usr/lib64/python2.7/json/decoder.py\", line 382, in raw_decode\n    raise ValueError(\"No JSON object could be decoded\")\nValueError: No JSON object could be decoded\n"}, "error": 1, "duration": XXXX, "type": "http", "span_id": "XXXX"}]]}
END RequestId: XXXX
REPORT RequestId: XXXX	Duration: XXXX ms	Billed Duration: XXXX ms	Memory Size: 1024 MB	Max Memory Used: XXXX MB	
XRAY TraceId: XXXX	SegmentId: XXXX	Sampled: true	
START RequestId: XXXX Version: $LATEST
{"e": XXXX, "m": "aws.lambda.enhanced.invocations", "t": ["region:us-east-1", "account_id:XXXX", "functionname:integration-dev-http-error_python27", "resource:integration-dev-http-error_python27", "cold_start:false", "memorysize:1024", "runtime:python2.7", "datadog_lambda:vXX", "dd_lambda_layer:datadog-python27_2.XX.0"], "v": 1}
HTTP GET https://httpstat.us/400/ Headers: ["Accept-Encoding:gzip, deflate", "Accept:*/*", "Connection:keep-alive", "User-Agent:python-requests/2.25.1", "x-datadog-parent-id:XXXX", "x-datadog-sampling-priority:1", "x-datadog-trace-id:XXXX"] Data: {}
2021-03-24 19:21:25.230 (-04:00)	de7a364c-72e7-4b41-8303-79d5fd1778b9	[ERROR]	[dd.trace_id=666 dd.span_id=12490543640940942221]	Error flushing metrics and events
Traceback (most recent call last):
  File "/opt/python/lib/python2.7/site-packages/datadog/threadstats/base.py", line 343, in flush
    self.reporter.flush_distributions(dists)
  File "/opt/python/lib/python2.7/site-packages/datadog/threadstats/reporters.py", line 24, in flush_distributions
    api.Distribution.send(distributions, compress_payload=self.compress_payload)
  File "/opt/python/lib/python2.7/site-packages/datadog/api/distributions.py", line 43, in send
    attach_host_name=attach_host_name, compress_payload=compress_payload, **series_dict
  File "/opt/python/lib/python2.7/site-packages/datadog/api/resources.py", line 88, in send
    compress_payload=compress_payload
  File "/opt/python/lib/python2.7/site-packages/datadog/api/api_client.py", line 166, in submit
    proxies=_proxies, verify=_cacert
  File "/opt/python/lib/python2.7/site-packages/datadog/api/http_client.py", line 100, in request
    proxies=proxies, verify=verify)
  File "/opt/python/lib/python2.7/site-packages/requests/sessions.py", line 542, in request
    resp = self.send(prep, **send_kwargs)
  File "/opt/python/lib/python2.7/site-packages/ddtrace/contrib/requests/connection.py", line 95, in _wrap_send
    response = func(*args, **kwargs)
  File "/opt/python/lib/python2.7/site-packages/datadog_lambda/patch.py", line 133, in _log_request
    _print_request_string(request)
  File "/opt/python/lib/python2.7/site-packages/datadog_lambda/patch.py", line 147, in _print_request_string
    data_dict = json.loads(data)
  File "/usr/lib64/python2.7/json/__init__.py", line 339, in loads
    return _default_decoder.decode(s)
  File "/usr/lib64/python2.7/json/decoder.py", line 364, in decode
    obj, end = self.raw_decode(s, idx=_w(s, 0).end())
  File "/usr/lib64/python2.7/json/decoder.py", line 382, in raw_decode
    raise ValueError("No JSON object could be decoded")
ValueError: No JSON object could be decoded{"traces": [[{"resource": "integration-dev-http-error_python27", "name": "aws.lambda", "service": "aws.lambda", "start": XXXX, "trace_id": "XXXX", "metrics": {"_sampling_priority_v1": 1, "system.pid": XXXX}, "parent_id": "XXXX", "meta": {"runtime-id": "XXXX", "request_id": "XXXX", "function_trigger.event_source": "sqs", "cold_start": "false", "datadog_lambda": "X.X.X", "function_arn": "arn:aws:lambda:us-east-1:601427279990:function:integration-dev-http-error_python27", "dd_trace": "X.X.X", "_dd.origin": "lambda", "resource_names": "integration-dev-http-error_python27", "function_trigger.event_source_arn": "arn:aws:sqs:us-east-2:123456789012:my-queue", "function_version": "$LATEST"}, "error": 0, "duration": XXXX, "type": "serverless", "span_id": "XXXX"}, {"resource": "requests.request", "name": "requests.request", "service": "aws.lambda", "start": XXXX, "trace_id": "XXXX", "metrics": {"_dd.measured": 1}, "parent_id": "XXXX", "meta": {"http.status_code": "400", "http.url": "https://httpstat.us/400/", "_dd.origin": "lambda", "http.method": "GET"}, "error": 0, "duration": XXXX, "type": "http", "span_id": "XXXX"}, {"resource": "requests.request", "name": "requests.request", "service": "aws.lambda", "start": XXXX, "trace_id": "XXXX", "metrics": {"_dd.measured": 1}, "parent_id": "XXXX", "meta": {"http.method": "POST", "http.url": "https://api.datadoghq.com/api/v1/distribution_points", "error.type": "exceptions.ValueError", "_dd.origin": "lambda", "error.msg": "No JSON object could be decoded", "error.stack": "Traceback (most recent call last):\n  File \"/opt/python/lib/python2.7/site-packages/ddtrace/contrib/requests/connection.py\", line 95, in _wrap_send\n    response = func(*args, **kwargs)\n  File \"/opt/python/lib/python2.7/site-packages/datadog_lambda/patch.py\", line 133, in _log_request\n    _print_request_string(request)\n  File \"/opt/python/lib/python2.7/site-packages/datadog_lambda/patch.py\", line 147, in _print_request_string\n    data_dict = json.loads(data)\n  File \"/usr/lib64/python2.7/json/__init__.py\", line 339, in loads\n    return _default_decoder.decode(s)\n  File \"/usr/lib64/python2.7/json/decoder.py\", line 364, in decode\n    obj, end = self.raw_decode(s, idx=_w(s, 0).end())\n  File \"/usr/lib64/python2.7/json/decoder.py\", line 382, in raw_decode\n    raise ValueError(\"No JSON object could be decoded\")\nValueError: No JSON object could be decoded\n"}, "error": 1, "duration": XXXX, "type": "http", "span_id": "XXXX"}]]}
END RequestId: XXXX
REPORT RequestId: XXXX	Duration: XXXX ms	Billed Duration: XXXX ms	Memory Size: 1024 MB	Max Memory Used: XXXX MB	
XRAY TraceId: XXXX	SegmentId: XXXX	Sampled: true	
