/var/runtime/botocore/vendored/requests/__init__.py:91: RequestsDependencyWarning: urllib3 (1.26.4) or chardet (4.0.0) doesn't match a supported version!
RequestsDependencyWarning)
START RequestId: XXXX Version: $LATEST
{"e": XXXX, "m": "aws.lambda.enhanced.invocations", "t": ["region:us-east-1", "account_id:XXXX", "functionname:integration-dev-sync-metrics_python27", "resource:integration-dev-sync-metrics_python27", "cold_start:true", "memorysize:1024", "runtime:python2.7", "datadog_lambda:vXX", "dd_lambda_layer:datadog-python27_2.XX.0"], "v": 1}
2021-03-24 18:59:01.400 (-04:00)	a2293d15-c5ed-428e-a30d-ef107f88d92d	[ERROR]	[dd.trace_id=8751116937135232972 dd.span_id=3649702443699507715]	Error flushing metrics and events
Traceback (most recent call last):
  File "/opt/python/lib/python2.7/site-packages/datadog/threadstats/base.py", line 343, in flush
    self.reporter.flush_distributions(dists)
  File "/opt/python/lib/python2.7/site-packages/datadog/threadstats/reporters.py", line 24, in flush_distributions
    api.Distribution.send(distributions, compress_payload=self.compress_payload)
  File "/opt/python/lib/python2.7/site-packages/datadog/api/distributions.py", line 43, in send
    attach_host_name=attach_host_name, compress_payload=compress_payload, **series_dict
  File "/opt/python/lib/python2.7/site-packages/datadog/api/resources.py", line 88, in send
    compress_payload=compress_payload
  File "/opt/python/lib/python2.7/site-packages/datadog/api/api_client.py", line 166, in submit
    proxies=_proxies, verify=_cacert
  File "/opt/python/lib/python2.7/site-packages/datadog/api/http_client.py", line 100, in request
    proxies=proxies, verify=verify)
  File "/opt/python/lib/python2.7/site-packages/datadog_lambda/patch.py", line 112, in _wrap_requests_request
    return func(*args, **kwargs)
  File "/opt/python/lib/python2.7/site-packages/requests/sessions.py", line 542, in request
    resp = self.send(prep, **send_kwargs)
  File "/opt/python/lib/python2.7/site-packages/datadog_lambda/patch.py", line 133, in _log_request
    _print_request_string(request)
  File "/opt/python/lib/python2.7/site-packages/datadog_lambda/patch.py", line 147, in _print_request_string
    data_dict = json.loads(data)
  File "/usr/lib64/python2.7/json/__init__.py", line 339, in loads
    return _default_decoder.decode(s)
  File "/usr/lib64/python2.7/json/decoder.py", line 364, in decode
    obj, end = self.raw_decode(s, idx=_w(s, 0).end())
  File "/usr/lib64/python2.7/json/decoder.py", line 382, in raw_decode
    raise ValueError("No JSON object could be decoded")
ValueError: No JSON object could be decodedEND RequestId: XXXX
REPORT RequestId: XXXX	Duration: XXXX ms	Billed Duration: XXXX ms	Memory Size: 1024 MB	Max Memory Used: XXXX MB	Init Duration: XXXX ms	
XRAY TraceId: XXXX	SegmentId: XXXX	Sampled: true	
START RequestId: XXXX Version: $LATEST
{"e": XXXX, "m": "aws.lambda.enhanced.invocations", "t": ["region:us-east-1", "account_id:XXXX", "functionname:integration-dev-sync-metrics_python27", "resource:integration-dev-sync-metrics_python27", "cold_start:false", "memorysize:1024", "runtime:python2.7", "datadog_lambda:vXX", "dd_lambda_layer:datadog-python27_2.XX.0"], "v": 1}
2021-03-24 18:59:02.457 (-04:00)	a80c19e5-aad1-4b75-bbe1-05496b3dcd5a	[ERROR]	[dd.trace_id=3794574581347819908 dd.span_id=707723148008120873]	Error flushing metrics and events
Traceback (most recent call last):
  File "/opt/python/lib/python2.7/site-packages/datadog/threadstats/base.py", line 343, in flush
    self.reporter.flush_distributions(dists)
  File "/opt/python/lib/python2.7/site-packages/datadog/threadstats/reporters.py", line 24, in flush_distributions
    api.Distribution.send(distributions, compress_payload=self.compress_payload)
  File "/opt/python/lib/python2.7/site-packages/datadog/api/distributions.py", line 43, in send
    attach_host_name=attach_host_name, compress_payload=compress_payload, **series_dict
  File "/opt/python/lib/python2.7/site-packages/datadog/api/resources.py", line 88, in send
    compress_payload=compress_payload
  File "/opt/python/lib/python2.7/site-packages/datadog/api/api_client.py", line 166, in submit
    proxies=_proxies, verify=_cacert
  File "/opt/python/lib/python2.7/site-packages/datadog/api/http_client.py", line 100, in request
    proxies=proxies, verify=verify)
  File "/opt/python/lib/python2.7/site-packages/datadog_lambda/patch.py", line 112, in _wrap_requests_request
    return func(*args, **kwargs)
  File "/opt/python/lib/python2.7/site-packages/requests/sessions.py", line 542, in request
    resp = self.send(prep, **send_kwargs)
  File "/opt/python/lib/python2.7/site-packages/datadog_lambda/patch.py", line 133, in _log_request
    _print_request_string(request)
  File "/opt/python/lib/python2.7/site-packages/datadog_lambda/patch.py", line 147, in _print_request_string
    data_dict = json.loads(data)
  File "/usr/lib64/python2.7/json/__init__.py", line 339, in loads
    return _default_decoder.decode(s)
  File "/usr/lib64/python2.7/json/decoder.py", line 364, in decode
    obj, end = self.raw_decode(s, idx=_w(s, 0).end())
  File "/usr/lib64/python2.7/json/decoder.py", line 382, in raw_decode
    raise ValueError("No JSON object could be decoded")
ValueError: No JSON object could be decodedEND RequestId: XXXX
REPORT RequestId: XXXX	Duration: XXXX ms	Billed Duration: XXXX ms	Memory Size: 1024 MB	Max Memory Used: XXXX MB	
XRAY TraceId: XXXX	SegmentId: XXXX	Sampled: true	
START RequestId: XXXX Version: $LATEST
{"e": XXXX, "m": "aws.lambda.enhanced.invocations", "t": ["region:us-east-1", "account_id:XXXX", "functionname:integration-dev-sync-metrics_python27", "resource:integration-dev-sync-metrics_python27", "cold_start:false", "memorysize:1024", "runtime:python2.7", "datadog_lambda:vXX", "dd_lambda_layer:datadog-python27_2.XX.0"], "v": 1}
2021-03-24 18:59:03.842 (-04:00)	cd9779f7-949a-4b2d-afad-3953dacc3ecd	[ERROR]	[dd.trace_id=666 dd.span_id=2604638816943755936]	Error flushing metrics and events
Traceback (most recent call last):
  File "/opt/python/lib/python2.7/site-packages/datadog/threadstats/base.py", line 343, in flush
    self.reporter.flush_distributions(dists)
  File "/opt/python/lib/python2.7/site-packages/datadog/threadstats/reporters.py", line 24, in flush_distributions
    api.Distribution.send(distributions, compress_payload=self.compress_payload)
  File "/opt/python/lib/python2.7/site-packages/datadog/api/distributions.py", line 43, in send
    attach_host_name=attach_host_name, compress_payload=compress_payload, **series_dict
  File "/opt/python/lib/python2.7/site-packages/datadog/api/resources.py", line 88, in send
    compress_payload=compress_payload
  File "/opt/python/lib/python2.7/site-packages/datadog/api/api_client.py", line 166, in submit
    proxies=_proxies, verify=_cacert
  File "/opt/python/lib/python2.7/site-packages/datadog/api/http_client.py", line 100, in request
    proxies=proxies, verify=verify)
  File "/opt/python/lib/python2.7/site-packages/datadog_lambda/patch.py", line 112, in _wrap_requests_request
    return func(*args, **kwargs)
  File "/opt/python/lib/python2.7/site-packages/requests/sessions.py", line 542, in request
    resp = self.send(prep, **send_kwargs)
  File "/opt/python/lib/python2.7/site-packages/datadog_lambda/patch.py", line 133, in _log_request
    _print_request_string(request)
  File "/opt/python/lib/python2.7/site-packages/datadog_lambda/patch.py", line 147, in _print_request_string
    data_dict = json.loads(data)
  File "/usr/lib64/python2.7/json/__init__.py", line 339, in loads
    return _default_decoder.decode(s)
  File "/usr/lib64/python2.7/json/decoder.py", line 364, in decode
    obj, end = self.raw_decode(s, idx=_w(s, 0).end())
  File "/usr/lib64/python2.7/json/decoder.py", line 382, in raw_decode
    raise ValueError("No JSON object could be decoded")
ValueError: No JSON object could be decodedEND RequestId: XXXX
REPORT RequestId: XXXX	Duration: XXXX ms	Billed Duration: XXXX ms	Memory Size: 1024 MB	Max Memory Used: XXXX MB	
XRAY TraceId: XXXX	SegmentId: XXXX	Sampled: true	
START RequestId: XXXX Version: $LATEST
{"e": XXXX, "m": "aws.lambda.enhanced.invocations", "t": ["region:us-east-1", "account_id:XXXX", "functionname:integration-dev-sync-metrics_python27", "resource:integration-dev-sync-metrics_python27", "cold_start:true", "memorysize:1024", "runtime:python2.7", "datadog_lambda:vXX", "dd_lambda_layer:datadog-python27_2.XX.0"], "v": 1}
2021-03-24 19:20:36.477 (-04:00)	baacf2e1-3c7a-4ed9-80b5-abeceab6eb32	[ERROR]	[dd.trace_id=1796430670625453018 dd.span_id=2048613948881817058]	Error flushing metrics and events
Traceback (most recent call last):
  File "/opt/python/lib/python2.7/site-packages/datadog/threadstats/base.py", line 343, in flush
    self.reporter.flush_distributions(dists)
  File "/opt/python/lib/python2.7/site-packages/datadog/threadstats/reporters.py", line 24, in flush_distributions
    api.Distribution.send(distributions, compress_payload=self.compress_payload)
  File "/opt/python/lib/python2.7/site-packages/datadog/api/distributions.py", line 43, in send
    attach_host_name=attach_host_name, compress_payload=compress_payload, **series_dict
  File "/opt/python/lib/python2.7/site-packages/datadog/api/resources.py", line 88, in send
    compress_payload=compress_payload
  File "/opt/python/lib/python2.7/site-packages/datadog/api/api_client.py", line 166, in submit
    proxies=_proxies, verify=_cacert
  File "/opt/python/lib/python2.7/site-packages/datadog/api/http_client.py", line 100, in request
    proxies=proxies, verify=verify)
  File "/opt/python/lib/python2.7/site-packages/datadog_lambda/patch.py", line 112, in _wrap_requests_request
    return func(*args, **kwargs)
  File "/opt/python/lib/python2.7/site-packages/requests/sessions.py", line 542, in request
    resp = self.send(prep, **send_kwargs)
  File "/opt/python/lib/python2.7/site-packages/datadog_lambda/patch.py", line 133, in _log_request
    _print_request_string(request)
  File "/opt/python/lib/python2.7/site-packages/datadog_lambda/patch.py", line 147, in _print_request_string
    data_dict = json.loads(data)
  File "/usr/lib64/python2.7/json/__init__.py", line 339, in loads
    return _default_decoder.decode(s)
  File "/usr/lib64/python2.7/json/decoder.py", line 364, in decode
    obj, end = self.raw_decode(s, idx=_w(s, 0).end())
  File "/usr/lib64/python2.7/json/decoder.py", line 382, in raw_decode
    raise ValueError("No JSON object could be decoded")
ValueError: No JSON object could be decodedEND RequestId: XXXX
REPORT RequestId: XXXX	Duration: XXXX ms	Billed Duration: XXXX ms	Memory Size: 1024 MB	Max Memory Used: XXXX MB	Init Duration: XXXX ms	
XRAY TraceId: XXXX	SegmentId: XXXX	Sampled: true	
START RequestId: XXXX Version: $LATEST
{"e": XXXX, "m": "aws.lambda.enhanced.invocations", "t": ["region:us-east-1", "account_id:XXXX", "functionname:integration-dev-sync-metrics_python27", "resource:integration-dev-sync-metrics_python27", "cold_start:false", "memorysize:1024", "runtime:python2.7", "datadog_lambda:vXX", "dd_lambda_layer:datadog-python27_2.XX.0"], "v": 1}
2021-03-24 19:20:37.852 (-04:00)	432e9e2d-0617-4a97-b965-9635664a251e	[ERROR]	[dd.trace_id=8551332106681539594 dd.span_id=3597284304410915315]	Error flushing metrics and events
Traceback (most recent call last):
  File "/opt/python/lib/python2.7/site-packages/datadog/threadstats/base.py", line 343, in flush
    self.reporter.flush_distributions(dists)
  File "/opt/python/lib/python2.7/site-packages/datadog/threadstats/reporters.py", line 24, in flush_distributions
    api.Distribution.send(distributions, compress_payload=self.compress_payload)
  File "/opt/python/lib/python2.7/site-packages/datadog/api/distributions.py", line 43, in send
    attach_host_name=attach_host_name, compress_payload=compress_payload, **series_dict
  File "/opt/python/lib/python2.7/site-packages/datadog/api/resources.py", line 88, in send
    compress_payload=compress_payload
  File "/opt/python/lib/python2.7/site-packages/datadog/api/api_client.py", line 166, in submit
    proxies=_proxies, verify=_cacert
  File "/opt/python/lib/python2.7/site-packages/datadog/api/http_client.py", line 100, in request
    proxies=proxies, verify=verify)
  File "/opt/python/lib/python2.7/site-packages/datadog_lambda/patch.py", line 112, in _wrap_requests_request
    return func(*args, **kwargs)
  File "/opt/python/lib/python2.7/site-packages/requests/sessions.py", line 542, in request
    resp = self.send(prep, **send_kwargs)
  File "/opt/python/lib/python2.7/site-packages/datadog_lambda/patch.py", line 133, in _log_request
    _print_request_string(request)
  File "/opt/python/lib/python2.7/site-packages/datadog_lambda/patch.py", line 147, in _print_request_string
    data_dict = json.loads(data)
  File "/usr/lib64/python2.7/json/__init__.py", line 339, in loads
    return _default_decoder.decode(s)
  File "/usr/lib64/python2.7/json/decoder.py", line 364, in decode
    obj, end = self.raw_decode(s, idx=_w(s, 0).end())
  File "/usr/lib64/python2.7/json/decoder.py", line 382, in raw_decode
    raise ValueError("No JSON object could be decoded")
ValueError: No JSON object could be decodedEND RequestId: XXXX
REPORT RequestId: XXXX	Duration: XXXX ms	Billed Duration: XXXX ms	Memory Size: 1024 MB	Max Memory Used: XXXX MB	
XRAY TraceId: XXXX	SegmentId: XXXX	Sampled: true	
START RequestId: XXXX Version: $LATEST
{"e": XXXX, "m": "aws.lambda.enhanced.invocations", "t": ["region:us-east-1", "account_id:XXXX", "functionname:integration-dev-sync-metrics_python27", "resource:integration-dev-sync-metrics_python27", "cold_start:false", "memorysize:1024", "runtime:python2.7", "datadog_lambda:vXX", "dd_lambda_layer:datadog-python27_2.XX.0"], "v": 1}
2021-03-24 19:20:39.243 (-04:00)	be47f68b-6e9f-4456-a51b-cd26f46911d3	[ERROR]	[dd.trace_id=666 dd.span_id=3835223350306656541]	Error flushing metrics and events
Traceback (most recent call last):
  File "/opt/python/lib/python2.7/site-packages/datadog/threadstats/base.py", line 343, in flush
    self.reporter.flush_distributions(dists)
  File "/opt/python/lib/python2.7/site-packages/datadog/threadstats/reporters.py", line 24, in flush_distributions
    api.Distribution.send(distributions, compress_payload=self.compress_payload)
  File "/opt/python/lib/python2.7/site-packages/datadog/api/distributions.py", line 43, in send
    attach_host_name=attach_host_name, compress_payload=compress_payload, **series_dict
  File "/opt/python/lib/python2.7/site-packages/datadog/api/resources.py", line 88, in send
    compress_payload=compress_payload
  File "/opt/python/lib/python2.7/site-packages/datadog/api/api_client.py", line 166, in submit
    proxies=_proxies, verify=_cacert
  File "/opt/python/lib/python2.7/site-packages/datadog/api/http_client.py", line 100, in request
    proxies=proxies, verify=verify)
  File "/opt/python/lib/python2.7/site-packages/datadog_lambda/patch.py", line 112, in _wrap_requests_request
    return func(*args, **kwargs)
  File "/opt/python/lib/python2.7/site-packages/requests/sessions.py", line 542, in request
    resp = self.send(prep, **send_kwargs)
  File "/opt/python/lib/python2.7/site-packages/datadog_lambda/patch.py", line 133, in _log_request
    _print_request_string(request)
  File "/opt/python/lib/python2.7/site-packages/datadog_lambda/patch.py", line 147, in _print_request_string
    data_dict = json.loads(data)
  File "/usr/lib64/python2.7/json/__init__.py", line 339, in loads
    return _default_decoder.decode(s)
  File "/usr/lib64/python2.7/json/decoder.py", line 364, in decode
    obj, end = self.raw_decode(s, idx=_w(s, 0).end())
  File "/usr/lib64/python2.7/json/decoder.py", line 382, in raw_decode
    raise ValueError("No JSON object could be decoded")
ValueError: No JSON object could be decodedEND RequestId: XXXX
REPORT RequestId: XXXX	Duration: XXXX ms	Billed Duration: XXXX ms	Memory Size: 1024 MB	Max Memory Used: XXXX MB	
XRAY TraceId: XXXX	SegmentId: XXXX	Sampled: true	
