/var/runtime/botocore/vendored/requests/__init__.py:91: RequestsDependencyWarning: urllib3 (1.26.4) or chardet (4.0.0) doesn't match a supported version!
RequestsDependencyWarning)
START RequestId: XXXX Version: $LATEST
{"m": "aws.lambda.enhanced.invocations", "v": 1, "e": XXXX, "t": ["region:us-east-1", "account_id:XXXX", "functionname:integration-dev-sync-metrics_python36", "resource:integration-dev-sync-metrics_python36", "cold_start:true", "memorysize:1024", "runtime:python3.6", "datadog_lambda:vXX", "dd_lambda_layer:datadog-python36_2.XX.0"]}
2021-03-24 18:59:06.604 (-04:00)	c0bd5227-010f-4186-98a7-537422926476	[ERROR]	[dd.trace_id=3876245140880863235 dd.span_id=5926125206477583376]	Error flushing metrics and events
Traceback (most recent call last):
  File "/opt/python/lib/python3.6/site-packages/datadog/threadstats/base.py", line 343, in flush
    self.reporter.flush_distributions(dists)
  File "/opt/python/lib/python3.6/site-packages/datadog/threadstats/reporters.py", line 24, in flush_distributions
    api.Distribution.send(distributions, compress_payload=self.compress_payload)
  File "/opt/python/lib/python3.6/site-packages/datadog/api/distributions.py", line 43, in send
    attach_host_name=attach_host_name, compress_payload=compress_payload, **series_dict
  File "/opt/python/lib/python3.6/site-packages/datadog/api/resources.py", line 88, in send
    compress_payload=compress_payload
  File "/opt/python/lib/python3.6/site-packages/datadog/api/api_client.py", line 166, in submit
    proxies=_proxies, verify=_cacert
  File "/opt/python/lib/python3.6/site-packages/datadog/api/http_client.py", line 100, in request
    proxies=proxies, verify=verify)
  File "/opt/python/lib/python3.6/site-packages/datadog_lambda/patch.py", line 112, in _wrap_requests_request
    return func(*args, **kwargs)
  File "/opt/python/lib/python3.6/site-packages/requests/sessions.py", line 542, in request
    resp = self.send(prep, **send_kwargs)
  File "/opt/python/lib/python3.6/site-packages/datadog_lambda/patch.py", line 133, in _log_request
    _print_request_string(request)
  File "/opt/python/lib/python3.6/site-packages/datadog_lambda/patch.py", line 147, in _print_request_string
    data_dict = json.loads(data)
  File "/var/lang/lib/python3.6/json/__init__.py", line 349, in loads
    s = s.decode(detect_encoding(s), 'surrogatepass')
UnicodeDecodeError: 'utf-8' codec can't decode byte 0x9c in position 1: invalid start byteEND RequestId: XXXX
REPORT RequestId: XXXX	Duration: XXXX ms	Billed Duration: XXXX ms	Memory Size: 1024 MB	Max Memory Used: XXXX MB	Init Duration: XXXX ms	
XRAY TraceId: XXXX	SegmentId: XXXX	Sampled: true	
START RequestId: XXXX Version: $LATEST
{"m": "aws.lambda.enhanced.invocations", "v": 1, "e": XXXX, "t": ["region:us-east-1", "account_id:XXXX", "functionname:integration-dev-sync-metrics_python36", "resource:integration-dev-sync-metrics_python36", "cold_start:false", "memorysize:1024", "runtime:python3.6", "datadog_lambda:vXX", "dd_lambda_layer:datadog-python36_2.XX.0"]}
2021-03-24 18:59:08.900 (-04:00)	8b613476-7811-4da7-83eb-dd07a184b409	[ERROR]	[dd.trace_id=7975085264115266549 dd.span_id=3487314250174954801]	Error flushing metrics and events
Traceback (most recent call last):
  File "/opt/python/lib/python3.6/site-packages/datadog/threadstats/base.py", line 343, in flush
    self.reporter.flush_distributions(dists)
  File "/opt/python/lib/python3.6/site-packages/datadog/threadstats/reporters.py", line 24, in flush_distributions
    api.Distribution.send(distributions, compress_payload=self.compress_payload)
  File "/opt/python/lib/python3.6/site-packages/datadog/api/distributions.py", line 43, in send
    attach_host_name=attach_host_name, compress_payload=compress_payload, **series_dict
  File "/opt/python/lib/python3.6/site-packages/datadog/api/resources.py", line 88, in send
    compress_payload=compress_payload
  File "/opt/python/lib/python3.6/site-packages/datadog/api/api_client.py", line 166, in submit
    proxies=_proxies, verify=_cacert
  File "/opt/python/lib/python3.6/site-packages/datadog/api/http_client.py", line 100, in request
    proxies=proxies, verify=verify)
  File "/opt/python/lib/python3.6/site-packages/datadog_lambda/patch.py", line 112, in _wrap_requests_request
    return func(*args, **kwargs)
  File "/opt/python/lib/python3.6/site-packages/requests/sessions.py", line 542, in request
    resp = self.send(prep, **send_kwargs)
  File "/opt/python/lib/python3.6/site-packages/datadog_lambda/patch.py", line 133, in _log_request
    _print_request_string(request)
  File "/opt/python/lib/python3.6/site-packages/datadog_lambda/patch.py", line 147, in _print_request_string
    data_dict = json.loads(data)
  File "/var/lang/lib/python3.6/json/__init__.py", line 349, in loads
    s = s.decode(detect_encoding(s), 'surrogatepass')
UnicodeDecodeError: 'utf-8' codec can't decode byte 0x9c in position 1: invalid start byteEND RequestId: XXXX
REPORT RequestId: XXXX	Duration: XXXX ms	Billed Duration: XXXX ms	Memory Size: 1024 MB	Max Memory Used: XXXX MB	
XRAY TraceId: XXXX	SegmentId: XXXX	Sampled: true	
START RequestId: XXXX Version: $LATEST
{"m": "aws.lambda.enhanced.invocations", "v": 1, "e": XXXX, "t": ["region:us-east-1", "account_id:XXXX", "functionname:integration-dev-sync-metrics_python36", "resource:integration-dev-sync-metrics_python36", "cold_start:false", "memorysize:1024", "runtime:python3.6", "datadog_lambda:vXX", "dd_lambda_layer:datadog-python36_2.XX.0"]}
2021-03-24 18:59:09.487 (-04:00)	84c30b6b-3f99-4cf0-8e90-d209868d9c4d	[ERROR]	[dd.trace_id=666 dd.span_id=2890437647928413560]	Error flushing metrics and events
Traceback (most recent call last):
  File "/opt/python/lib/python3.6/site-packages/datadog/threadstats/base.py", line 343, in flush
    self.reporter.flush_distributions(dists)
  File "/opt/python/lib/python3.6/site-packages/datadog/threadstats/reporters.py", line 24, in flush_distributions
    api.Distribution.send(distributions, compress_payload=self.compress_payload)
  File "/opt/python/lib/python3.6/site-packages/datadog/api/distributions.py", line 43, in send
    attach_host_name=attach_host_name, compress_payload=compress_payload, **series_dict
  File "/opt/python/lib/python3.6/site-packages/datadog/api/resources.py", line 88, in send
    compress_payload=compress_payload
  File "/opt/python/lib/python3.6/site-packages/datadog/api/api_client.py", line 166, in submit
    proxies=_proxies, verify=_cacert
  File "/opt/python/lib/python3.6/site-packages/datadog/api/http_client.py", line 100, in request
    proxies=proxies, verify=verify)
  File "/opt/python/lib/python3.6/site-packages/datadog_lambda/patch.py", line 112, in _wrap_requests_request
    return func(*args, **kwargs)
  File "/opt/python/lib/python3.6/site-packages/requests/sessions.py", line 542, in request
    resp = self.send(prep, **send_kwargs)
  File "/opt/python/lib/python3.6/site-packages/datadog_lambda/patch.py", line 133, in _log_request
    _print_request_string(request)
  File "/opt/python/lib/python3.6/site-packages/datadog_lambda/patch.py", line 147, in _print_request_string
    data_dict = json.loads(data)
  File "/var/lang/lib/python3.6/json/__init__.py", line 349, in loads
    s = s.decode(detect_encoding(s), 'surrogatepass')
UnicodeDecodeError: 'utf-8' codec can't decode byte 0x9c in position 1: invalid start byteEND RequestId: XXXX
REPORT RequestId: XXXX	Duration: XXXX ms	Billed Duration: XXXX ms	Memory Size: 1024 MB	Max Memory Used: XXXX MB	
XRAY TraceId: XXXX	SegmentId: XXXX	Sampled: true	
/var/runtime/botocore/vendored/requests/__init__.py:91: RequestsDependencyWarning: urllib3 (1.26.4) or chardet (4.0.0) doesn't match a supported version!
RequestsDependencyWarning)
START RequestId: XXXX Version: $LATEST
{"m": "aws.lambda.enhanced.invocations", "v": 1, "e": XXXX, "t": ["region:us-east-1", "account_id:XXXX", "functionname:integration-dev-sync-metrics_python36", "resource:integration-dev-sync-metrics_python36", "cold_start:true", "memorysize:1024", "runtime:python3.6", "datadog_lambda:vXX", "dd_lambda_layer:datadog-python36_2.XX.0"]}
2021-03-24 19:20:41.883 (-04:00)	ed59044a-c056-4614-ad3d-79f2ff9954b0	[ERROR]	[dd.trace_id=4383610482127367473 dd.span_id=8154459864964820964]	Error flushing metrics and events
Traceback (most recent call last):
  File "/opt/python/lib/python3.6/site-packages/datadog/threadstats/base.py", line 343, in flush
    self.reporter.flush_distributions(dists)
  File "/opt/python/lib/python3.6/site-packages/datadog/threadstats/reporters.py", line 24, in flush_distributions
    api.Distribution.send(distributions, compress_payload=self.compress_payload)
  File "/opt/python/lib/python3.6/site-packages/datadog/api/distributions.py", line 43, in send
    attach_host_name=attach_host_name, compress_payload=compress_payload, **series_dict
  File "/opt/python/lib/python3.6/site-packages/datadog/api/resources.py", line 88, in send
    compress_payload=compress_payload
  File "/opt/python/lib/python3.6/site-packages/datadog/api/api_client.py", line 166, in submit
    proxies=_proxies, verify=_cacert
  File "/opt/python/lib/python3.6/site-packages/datadog/api/http_client.py", line 100, in request
    proxies=proxies, verify=verify)
  File "/opt/python/lib/python3.6/site-packages/datadog_lambda/patch.py", line 112, in _wrap_requests_request
    return func(*args, **kwargs)
  File "/opt/python/lib/python3.6/site-packages/requests/sessions.py", line 542, in request
    resp = self.send(prep, **send_kwargs)
  File "/opt/python/lib/python3.6/site-packages/datadog_lambda/patch.py", line 133, in _log_request
    _print_request_string(request)
  File "/opt/python/lib/python3.6/site-packages/datadog_lambda/patch.py", line 147, in _print_request_string
    data_dict = json.loads(data)
  File "/var/lang/lib/python3.6/json/__init__.py", line 349, in loads
    s = s.decode(detect_encoding(s), 'surrogatepass')
UnicodeDecodeError: 'utf-8' codec can't decode byte 0x9c in position 1: invalid start byteEND RequestId: XXXX
REPORT RequestId: XXXX	Duration: XXXX ms	Billed Duration: XXXX ms	Memory Size: 1024 MB	Max Memory Used: XXXX MB	Init Duration: XXXX ms	
XRAY TraceId: XXXX	SegmentId: XXXX	Sampled: true	
START RequestId: XXXX Version: $LATEST
{"m": "aws.lambda.enhanced.invocations", "v": 1, "e": XXXX, "t": ["region:us-east-1", "account_id:XXXX", "functionname:integration-dev-sync-metrics_python36", "resource:integration-dev-sync-metrics_python36", "cold_start:false", "memorysize:1024", "runtime:python3.6", "datadog_lambda:vXX", "dd_lambda_layer:datadog-python36_2.XX.0"]}
2021-03-24 19:20:43.352 (-04:00)	9e1c6ebc-582c-462d-9dc9-9b4dd45b73e3	[ERROR]	[dd.trace_id=8144671962745851543 dd.span_id=7269972712812607837]	Error flushing metrics and events
Traceback (most recent call last):
  File "/opt/python/lib/python3.6/site-packages/datadog/threadstats/base.py", line 343, in flush
    self.reporter.flush_distributions(dists)
  File "/opt/python/lib/python3.6/site-packages/datadog/threadstats/reporters.py", line 24, in flush_distributions
    api.Distribution.send(distributions, compress_payload=self.compress_payload)
  File "/opt/python/lib/python3.6/site-packages/datadog/api/distributions.py", line 43, in send
    attach_host_name=attach_host_name, compress_payload=compress_payload, **series_dict
  File "/opt/python/lib/python3.6/site-packages/datadog/api/resources.py", line 88, in send
    compress_payload=compress_payload
  File "/opt/python/lib/python3.6/site-packages/datadog/api/api_client.py", line 166, in submit
    proxies=_proxies, verify=_cacert
  File "/opt/python/lib/python3.6/site-packages/datadog/api/http_client.py", line 100, in request
    proxies=proxies, verify=verify)
  File "/opt/python/lib/python3.6/site-packages/datadog_lambda/patch.py", line 112, in _wrap_requests_request
    return func(*args, **kwargs)
  File "/opt/python/lib/python3.6/site-packages/requests/sessions.py", line 542, in request
    resp = self.send(prep, **send_kwargs)
  File "/opt/python/lib/python3.6/site-packages/datadog_lambda/patch.py", line 133, in _log_request
    _print_request_string(request)
  File "/opt/python/lib/python3.6/site-packages/datadog_lambda/patch.py", line 147, in _print_request_string
    data_dict = json.loads(data)
  File "/var/lang/lib/python3.6/json/__init__.py", line 349, in loads
    s = s.decode(detect_encoding(s), 'surrogatepass')
UnicodeDecodeError: 'utf-8' codec can't decode byte 0x9c in position 1: invalid start byteEND RequestId: XXXX
REPORT RequestId: XXXX	Duration: XXXX ms	Billed Duration: XXXX ms	Memory Size: 1024 MB	Max Memory Used: XXXX MB	
XRAY TraceId: XXXX	SegmentId: XXXX	Sampled: true	
START RequestId: XXXX Version: $LATEST
{"m": "aws.lambda.enhanced.invocations", "v": 1, "e": XXXX, "t": ["region:us-east-1", "account_id:XXXX", "functionname:integration-dev-sync-metrics_python36", "resource:integration-dev-sync-metrics_python36", "cold_start:false", "memorysize:1024", "runtime:python3.6", "datadog_lambda:vXX", "dd_lambda_layer:datadog-python36_2.XX.0"]}
2021-03-24 19:20:44.708 (-04:00)	27836451-9fa0-419e-9e7e-cee5f41d0327	[ERROR]	[dd.trace_id=666 dd.span_id=1350760370002200261]	Error flushing metrics and events
Traceback (most recent call last):
  File "/opt/python/lib/python3.6/site-packages/datadog/threadstats/base.py", line 343, in flush
    self.reporter.flush_distributions(dists)
  File "/opt/python/lib/python3.6/site-packages/datadog/threadstats/reporters.py", line 24, in flush_distributions
    api.Distribution.send(distributions, compress_payload=self.compress_payload)
  File "/opt/python/lib/python3.6/site-packages/datadog/api/distributions.py", line 43, in send
    attach_host_name=attach_host_name, compress_payload=compress_payload, **series_dict
  File "/opt/python/lib/python3.6/site-packages/datadog/api/resources.py", line 88, in send
    compress_payload=compress_payload
  File "/opt/python/lib/python3.6/site-packages/datadog/api/api_client.py", line 166, in submit
    proxies=_proxies, verify=_cacert
  File "/opt/python/lib/python3.6/site-packages/datadog/api/http_client.py", line 100, in request
    proxies=proxies, verify=verify)
  File "/opt/python/lib/python3.6/site-packages/datadog_lambda/patch.py", line 112, in _wrap_requests_request
    return func(*args, **kwargs)
  File "/opt/python/lib/python3.6/site-packages/requests/sessions.py", line 542, in request
    resp = self.send(prep, **send_kwargs)
  File "/opt/python/lib/python3.6/site-packages/datadog_lambda/patch.py", line 133, in _log_request
    _print_request_string(request)
  File "/opt/python/lib/python3.6/site-packages/datadog_lambda/patch.py", line 147, in _print_request_string
    data_dict = json.loads(data)
  File "/var/lang/lib/python3.6/json/__init__.py", line 349, in loads
    s = s.decode(detect_encoding(s), 'surrogatepass')
UnicodeDecodeError: 'utf-8' codec can't decode byte 0x9c in position 1: invalid start byteEND RequestId: XXXX
REPORT RequestId: XXXX	Duration: XXXX ms	Billed Duration: XXXX ms	Memory Size: 1024 MB	Max Memory Used: XXXX MB	
XRAY TraceId: XXXX	SegmentId: XXXX	Sampled: true	
